Workbook

Sheet สรุป
F1: ตั้งแต่วันที่ | G1: ถึงวันที่
F2: 46182 | G2: 46225 | J2: เพิ่มสโตร์ไซต์งานจากคอลัมน์นี้
B3: อัพเดทปัจจุบัน | C3: =TODAY() -> 46226 | F3: สโตร์ | J3: ไซต์งาน | R3: อื่นๆ | V3: ยอดตั้งต้น/ปรับยอด | Z3: สถานที่
F4: 1 | G4: 2 | H4: 3 | I4: 4 | J4: 5 | K4: 6 | L4: 7 | M4: 8 | N4: 9 | O4: 10 | P4: 11 | Q4: 12 | R4: 13 | Y4: 1 | Z4: 2 | AA4: 3 | AB4: 4 | AC4: 5 | AD4: 6 | AE4: 7 | AF4: 8 | AG4: 9 | AH4: 10 | AI4: 11 | AJ4: 12 | AK4: 13
B5: หมวดหมู่ | C5: รายการวัสดุ-อุปกรณ์ | D5: จำนวนรวม | E5: หน่วย | F5: สโตร์พงษ์เพชร | G5: สโตร์ออฟฟิศ | H5: สโตร์รัตนา | I5: สโตร์ไทรน้อย | J5: เอกมัย | K5: วอลโว่ | L5: งานซ่อม | M5: กบินทร์บุรี | N5: โกดังพี่เบิ้ล | O5: โรงเรียนแนช | P5: โตโยต้า นครพิงค์ | Q5: เช่า | R5: ร้านซ่อม | S5: หมายเหตุ | T5: ร้านค้า | U5: Column1 | V5: รายการวัสดุ-อุปกรณ์2 | W5: จำนวนรวม3 | X5: หน่วย4 | Y5: สโตร์พงษ์เพชร | Z5: สโตร์ออฟฟิศ | AA5: สโตร์รัตนา | AB5: สโตร์ไทรน้อย | AC5: เอกมัย | AD5: วอลโว่ | AE5: งานซ่อม | AF5: กบินทร์บุรี | AG5: โกดังพี่เบิ้ล | AH5: โรงเรียนแนช | AI5: โตโยต้า นครพิงค์ | AJ5: เช่า | AK5: ร้านซ่อม | AL5: Column18
B6: Safety | C6: เข็มขัดเซฟตี้ | D6: =SUMIF(F6:T6,">0") -> 8 | E6: อัน | F6: =Y6+SUMIFS('บันทึกของเข้า-ออก'!$J:$J,'บันทึกของเข้า-ออก'!$B:$B,สรุป!$C6,'บันทึกของเข้า-ออก'!$L:$L,สรุป!F$5,'บันทึกของเข้า-ออก'!$I:$I,">="&สรุป!$F$2,'บันทึกของเข้า-ออก'!$I:$I,"<="&สรุป!$G$2)-SUMIFS('บันทึกของเข้า-ออก'!$E:$E,'บันทึกของเข้า-ออก'!$B:$B,สรุป!$C6,'บันทึกของเข้า-ออก'!$F:$F,สรุป!F$5,'บันทึกของเข้า-ออก'!$D:$D,">="&สรุป!$F$2,'บันทึกของเข้า-ออก'!$D:$D,"<="&สรุป!$G$2) -> 0 | G6: =Z6+SUMIFS('บันทึกของเข้า-ออก'!$J:$J,'บันทึกของเข้า-ออก'!$B:$B,สรุป!$C6,'บันทึกของเข้า-ออก'!$L:$L,สรุป!G$5,'บันทึกของเข้า-ออก'!$I:$I,">="&สรุป!$F$2,'บันทึกของเข้า-ออก'!$I:$I,"<="&สรุป!$G$2)-SUMIFS('บันทึกของเข้า-ออก'!$E:$E,'บันทึกของเข้า-ออก'!$B:$B,สรุป!$C6,'บันทึกของเข้า-ออก'!$F:$F,สรุป!G$5,'บันทึกของเข้า-ออก'!$D:$D,">="&สรุป!$F$2,'บันทึกของเข้า-ออก'!$D:$D,"<="&สรุป!$G$2) -> 0 | H6: =AA6+SUMIFS('บันทึกของเข้า-ออก'!$J:$J,'บันทึกของเข้า-ออก'!$B:$B,สรุป!$C6,'บันทึกของเข้า-ออก'!$L:$L,สรุป!H$5,'บันทึกของเข้า-ออก'!$I:$I,">="&สรุป!$F$2,'บันทึกของเข้า-ออก'!$I:$I,"<="&สรุป!$G$2)-SUMIFS('บันทึกของเข้า-ออก'!$E:$E,'บันทึกของเข้า-ออก'!$B:$B,สรุป!$C6,'บันทึกของเข้า-ออก'!$F:$F,สรุป!H$5,'บันทึกของเข้า-ออก'!$D:$D,">="&สรุป!$F$2,'บันทึกของเข้า-ออก'!$D:$D,"<="&สรุป!$G$2) -> 1 | I6: =AB6+SUMIFS('บันทึกของเข้า-ออก'!$J:$J,'บันทึกของเข้า-ออก'!$B:$B,สรุป!$C6,'บันทึกของเข้า-ออก'!$L:$L,สรุป!I$5,'บันทึกของเข้า-ออก'!$I:$I,">="&สรุป!$F$2,'บันทึกของเข้า-ออก'!$I:$I,"<="&สรุป!$G$2)-SUMIFS('บันทึกของเข้า-ออก'!$E:$E,'บันทึกของเข้า-ออก'!$B:$B,สรุป!$C6,'บันทึกของเข้า-ออก'!$F:$F,สรุป!I$5,'บันทึกของเข้า-ออก'!$D:$D,">="&สรุป!$F$2,'บันทึกของเข้า-ออก'!$D:$D,"<="&สรุป!$G$2) -> 0 | J6: =AC6+SUMIFS('บันทึกของเข้า-ออก'!$J:$J,'บันทึกของเข้า-ออก'!$B:$B,สรุป!$C6,'บันทึกของเข้า-ออก'!$L:$L,สรุป!J$5,'บันทึกของเข้า-ออก'!$I:$I,">="&สรุป!$F$2,'บันทึกของเข้า-ออก'!$I:$I,"<="&สรุป!$G$2)-SUMIFS('บันทึกของเข้า-ออก'!$E:$E,'บันทึกของเข้า-ออก'!$B:$B,สรุป!$C6,'บันทึกของเข้า-ออก'!$F:$F,สรุป!J$5,'บันทึกของเข้า-ออก'!$D:$D,">="&สรุป!$F$2,'บันทึกของเข้า-ออก'!$D:$D,"<="&สรุป!$G$2) -> 5 | K6: =AD6+SUMIFS('บันทึกของเข้า-ออก'!$J:$J,'บันทึกของเข้า-ออก'!$B:$B,สรุป!$C6,'บันทึกของเข้า-ออก'!$L:$L,สรุป!K$5,'บันทึกของเข้า-ออก'!$I:$I,">="&สรุป!$F$2,'บันทึกของเข้า-ออก'!$I:$I,"<="&สรุป!$G$2)-SUMIFS('บันทึกของเข้า-ออก'!$E:$E,'บันทึกของเข้า-ออก'!$B:$B,สรุป!$C6,'บันทึกของเข้า-ออก'!$F:$F,สรุป!K$5,'บันทึกของเข้า-ออก'!$D:$D,">="&สรุป!$F$2,'บันทึกของเข้า-ออก'!$D:$D,"<="&สรุป!$G$2) -> 0 | L6: =AE6+SUMIFS('บันทึกของเข้า-ออก'!$J:$J,'บันทึกของเข้า-ออก'!$B:$B,สรุป!$C6,'บันทึกของเข้า-ออก'!$L:$L,สรุป!L$5,'บันทึกของเข้า-ออก'!$I:$I,">="&สรุป!$F$2,'บันทึกของเข้า-ออก'!$I:$I,"<="&สรุป!$G$2)-SUMIFS('บันทึกของเข้า-ออก'!$E:$E,'บันทึกของเข้า-ออก'!$B:$B,สรุป!$C6,'บันทึกของเข้า-ออก'!$F:$F,สรุป!L$5,'บันทึกของเข้า-ออก'!$D:$D,">="&สรุป!$F$2,'บันทึกของเข้า-ออก'!$D:$D,"<="&สรุป!$G$2) -> 0 | M6: =AF6+SUMIFS('บันทึกของเข้า-ออก'!$J:$J,'บันทึกของเข้า-ออก'!$B:$B,สรุป!$C6,'บันทึกของเข้า-ออก'!$L:$L,สรุป!M$5,'บันทึกของเข้า-ออก'!$I:$I,">="&สรุป!$F$2,'บันทึกของเข้า-ออก'!$I:$I,"<="&สรุป!$G$2)-SUMIFS('บันทึกของเข้า-ออก'!$E:$E,'บันทึกของเข้า-ออก'!$B:$B,สรุป!$C6,'บันทึกของเข้า-ออก'!$F:$F,สรุป!M$5,'บันทึกของเข้า-ออก'!$D:$D,">="&สรุป!$F$2,'บันทึกของเข้า-ออก'!$D:$D,"<="&สรุป!$G$2) -> 0 | ... R6: =AK6+SUMIFS('บันทึกของเข้า-ออก'!$J:$J,'บันทึกของเข้า-ออก'!$B:$B,สรุป!$C6,'บันทึกของเข้า-ออก'!$L:$L,สรุป!R$5,'บันทึกของเข้า-ออก'!$I:$I,">="&สรุป!$F$2,'บันทึกของเข้า-ออก'!$I:$I,"<="&สรุป!$G$2)-SUMIFS('บันทึกของเข้า-ออก'!$E:$E,'บันทึกของเข้า-ออก'!$B:$B,สรุป!$C6,'บันทึกของเข้า-ออก'!$F:$F,สรุป!R$5,'บันทึกของเข้า-ออก'!$D:$D,">="&สรุป!$F$2,'บันทึกของเข้า-ออก'!$D:$D,"<="&สรุป!$G$2) -> 0 | V6: =C6 -> เข็มขัดเซฟตี้ | W6: 8 | X6: อัน | Y6: 0 | Z6: 0 | AA6: 3 | AB6: 0 | AC6: 5 | AD6: 0 | AE6: 0 | AF6: 0 | AG6: 0 | AH6: 0 | AI6: 0 | AJ6: 0 | AK6: 0
B7: Safety | C7: เสื้อสะท้อนแสง | D7: =SUMIF(F7:T7,">0") -> 0 | E7: ตัว | F7: =Y7+SUMIFS('บันทึกของเข้า-ออก'!$J:$J,'บันทึกของเข้า-ออก'!$B:$B,สรุป!$C7,'บันทึกของเข้า-ออก'!$L:$L,สรุป!F$5,'บันทึกของเข้า-ออก'!$I:$I,">="&สรุป!$F$2,'บันทึกของเข้า-ออก'!$I:$I,"<="&สรุป!$G$2)-SUMIFS('บันทึกของเข้า-ออก'!$E:$E,'บันทึกของเข้า-ออก'!$B:$B,สรุป!$C7,'บันทึกของเข้า-ออก'!$F:$F,สรุป!F$5,'บันทึกของเข้า-ออก'!$D:$D,">="&สรุป!$F$2,'บันทึกของเข้า-ออก'!$D:$D,"<="&สรุป!$G$2) -> 0 | G7: =Z7+SUMIFS('บันทึกของเข้า-ออก'!$J:$J,'บันทึกของเข้า-ออก'!$B:$B,สรุป!$C7,'บันทึกของเข้า-ออก'!$L:$L,สรุป!G$5,'บันทึกของเข้า-ออก'!$I:$I,">="&สรุป!$F$2,'บันทึกของเข้า-ออก'!$I:$I,"<="&สรุป!$G$2)-SUMIFS('บันทึกของเข้า-ออก'!$E:$E,'บันทึกของเข้า-ออก'!$B:$B,สรุป!$C7,'บันทึกของเข้า-ออก'!$F:$F,สรุป!G$5,'บันทึกของเข้า-ออก'!$D:$D,">="&สรุป!$F$2,'บันทึกของเข้า-ออก'!$D:$D,"<="&สรุป!$G$2) -> 0 | H7: =AA7+SUMIFS('บันทึกของเข้า-ออก'!$J:$J,'บันทึกของเข้า-ออก'!$B:$B,สรุป!$C7,'บันทึกของเข้า-ออก'!$L:$L,สรุป!H$5,'บันทึกของเข้า-ออก'!$I:$I,">="&สรุป!$F$2,'บันทึกของเข้า-ออก'!$I:$I,"<="&สรุป!$G$2)-SUMIFS('บันทึกของเข้า-ออก'!$E:$E,'บันทึกของเข้า-ออก'!$B:$B,สรุป!$C7,'บันทึกของเข้า-ออก'!$F:$F,สรุป!H$5,'บันทึกของเข้า-ออก'!$D:$D,">="&สรุป!$F$2,'บันทึกของเข้า-ออก'!$D:$D,"<="&สรุป!$G$2) -> 0 | I7: =AB7+SUMIFS('บันทึกของเข้า-ออก'!$J:$J,'บันทึกของเข้า-ออก'!$B:$B,สรุป!$C7,'บันทึกของเข้า-ออก'!$L:$L,สรุป!I$5,'บันทึกของเข้า-ออก'!$I:$I,">="&สรุป!$F$2,'บันทึกของเข้า-ออก'!$I:$I,"<="&สรุป!$G$2)-SUMIFS('บันทึกของเข้า-ออก'!$E:$E,'บันทึกของเข้า-ออก'!$B:$B,สรุป!$C7,'บันทึกของเข้า-ออก'!$F:$F,สรุป!I$5,'บันทึกของเข้า-ออก'!$D:$D,">="&สรุป!$F$2,'บันทึกของเข้า-ออก'!$D:$D,"<="&สรุป!$G$2) -> 0 | J7: =AC7+SUMIFS('บันทึกของเข้า-ออก'!$J:$J,'บันทึกของเข้า-ออก'!$B:$B,สรุป!$C7,'บันทึกของเข้า-ออก'!$L:$L,สรุป!J$5,'บันทึกของเข้า-ออก'!$I:$I,">="&สรุป!$F$2,'บันทึกของเข้า-ออก'!$I:$I,"<="&สรุป!$G$2)-SUMIFS('บันทึกของเข้า-ออก'!$E:$E,'บันทึกของเข้า-ออก'!$B:$B,สรุป!$C7,'บันทึกของเข้า-ออก'!$F:$F,สรุป!J$5,'บันทึกของเข้า-ออก'!$D:$D,">="&สรุป!$F$2,'บันทึกของเข้า-ออก'!$D:$D,"<="&สรุป!$G$2) -> 0 | K7: =AD7+SUMIFS('บันทึกของเข้า-ออก'!$J:$J,'บันทึกของเข้า-ออก'!$B:$B,สรุป!$C7,'บันทึกของเข้า-ออก'!$L:$L,สรุป!K$5,'บันทึกของเข้า-ออก'!$I:$I,">="&สรุป!$F$2,'บันทึกของเข้า-ออก'!$I:$I,"<="&สรุป!$G$2)-SUMIFS('บันทึกของเข้า-ออก'!$E:$E,'บันทึกของเข้า-ออก'!$B:$B,สรุป!$C7,'บันทึกของเข้า-ออก'!$F:$F,สรุป!K$5,'บันทึกของเข้า-ออก'!$D:$D,">="&สรุป!$F$2,'บันทึกของเข้า-ออก'!$D:$D,"<="&สรุป!$G$2) -> 0 | L7: =AE7+SUMIFS('บันทึกของเข้า-ออก'!$J:$J,'บันทึกของเข้า-ออก'!$B:$B,สรุป!$C7,'บันทึกของเข้า-ออก'!$L:$L,สรุป!L$5,'บันทึกของเข้า-ออก'!$I:$I,">="&สรุป!$F$2,'บันทึกของเข้า-ออก'!$I:$I,"<="&สรุป!$G$2)-SUMIFS('บันทึกของเข้า-ออก'!$E:$E,'บันทึกของเข้า-ออก'!$B:$B,สรุป!$C7,'บันทึกของเข้า-ออก'!$F:$F,สรุป!L$5,'บันทึกของเข้า-ออก'!$D:$D,">="&สรุป!$F$2,'บันทึกของเข้า-ออก'!$D:$D,"<="&สรุป!$G$2) -> 0 | M7: =AF7+SUMIFS('บันทึกของเข้า-ออก'!$J:$J,'บันทึกของเข้า-ออก'!$B:$B,สรุป!$C7,'บันทึกของเข้า-ออก'!$L:$L,สรุป!M$5,'บันทึกของเข้า-ออก'!$I:$I,">="&สรุป!$F$2,'บันทึกของเข้า-ออก'!$I:$I,"<="&สรุป!$G$2)-SUMIFS('บันทึกของเข้า-ออก'!$E:$E,'บันทึกของเข้า-ออก'!$B:$B,สรุป!$C7,'บันทึกของเข้า-ออก'!$F:$F,สรุป!M$5,'บันทึกของเข้า-ออก'!$D:$D,">="&สรุป!$F$2,'บันทึกของเข้า-ออก'!$D:$D,"<="&สรุป!$G$2) -> 0 | ... S7: =AL7+SUMIFS('บันทึกของเข้า-ออก'!$J:$J,'บันทึกของเข้า-ออก'!$B:$B,สรุป!$C7,'บันทึกของเข้า-ออก'!$L:$L,สรุป!S$5,'บันทึกของเข้า-ออก'!$I:$I,">="&สรุป!$F$2,'บันทึกของเข้า-ออก'!$I:$I,"<="&สรุป!$G$2)-SUMIFS('บันทึกของเข้า-ออก'!$E:$E,'บันทึกของเข้า-ออก'!$B:$B,สรุป!$C7,'บันทึกของเข้า-ออก'!$F:$F,สรุป!S$5,'บันทึกของเข้า-ออก'!$D:$D,">="&สรุป!$F$2,'บันทึกของเข้า-ออก'!$D:$D,"<="&สรุป!$G$2) -> 0 | V7: เสื้อสะท้อนแสง | W7: 3 | X7: ตัว | Y7: 0 | Z7: 0 | AA7: 0 | AB7: 0 | AC7: 0 | AD7: 0 | AE7: 0 | AF7: 0 | AG7: 0 | AH7: 0 | AI7: 0 | AJ7: 0 | AK7: 0
B8: Safety | C8: ผ้ากันสะเก็ดไฟ | D8: =SUMIF(F8:T8,">0") -> 0 | E8: ผืน | F8: =Y8+SUMIFS('บันทึกของเข้า-ออก'!$J:$J,'บันทึกของเข้า-ออก'!$B:$B,สรุป!$C8,'บันทึกของเข้า-ออก'!$L:$L,สรุป!F$5,'บันทึกของเข้า-ออก'!$I:$I,">="&สรุป!$F$2,'บันทึกของเข้า-ออก'!$I:$I,"<="&สรุป!$G$2)-SUMIFS('บันทึกของเข้า-ออก'!$E:$E,'บันทึกของเข้า-ออก'!$B:$B,สรุป!$C8,'บันทึกของเข้า-ออก'!$F:$F,สรุป!F$5,'บันทึกของเข้า-ออก'!$D:$D,">="&สรุป!$F$2,'บันทึกของเข้า-ออก'!$D:$D,"<="&สรุป!$G$2) -> 0 | G8: =Z8+SUMIFS('บันทึกของเข้า-ออก'!$J:$J,'บันทึกของเข้า-ออก'!$B:$B,สรุป!$C8,'บันทึกของเข้า-ออก'!$L:$L,สรุป!G$5,'บันทึกของเข้า-ออก'!$I:$I,">="&สรุป!$F$2,'บันทึกของเข้า-ออก'!$I:$I,"<="&สรุป!$G$2)-SUMIFS('บันทึกของเข้า-ออก'!$E:$E,'บันทึกของเข้า-ออก'!$B:$B,สรุป!$C8,'บันทึกของเข้า-ออก'!$F:$F,สรุป!G$5,'บันทึกของเข้า-ออก'!$D:$D,">="&สรุป!$F$2,'บันทึกของเข้า-ออก'!$D:$D,"<="&สรุป!$G$2) -> 0 | H8: =AA8+SUMIFS('บันทึกของเข้า-ออก'!$J:$J,'บันทึกของเข้า-ออก'!$B:$B,สรุป!$C8,'บันทึกของเข้า-ออก'!$L:$L,สรุป!H$5,'บันทึกของเข้า-ออก'!$I:$I,">="&สรุป!$F$2,'บันทึกของเข้า-ออก'!$I:$I,"<="&สรุป!$G$2)-SUMIFS('บันทึกของเข้า-ออก'!$E:$E,'บันทึกของเข้า-ออก'!$B:$B,สรุป!$C8,'บันทึกของเข้า-ออก'!$F:$F,สรุป!H$5,'บันทึกของเข้า-ออก'!$D:$D,">="&สรุป!$F$2,'บันทึกของเข้า-ออก'!$D:$D,"<="&สรุป!$G$2) -> 0 | I8: =AB8+SUMIFS('บันทึกของเข้า-ออก'!$J:$J,'บันทึกของเข้า-ออก'!$B:$B,สรุป!$C8,'บันทึกของเข้า-ออก'!$L:$L,สรุป!I$5,'บันทึกของเข้า-ออก'!$I:$I,">="&สรุป!$F$2,'บันทึกของเข้า-ออก'!$I:$I,"<="&สรุป!$G$2)-SUMIFS('บันทึกของเข้า-ออก'!$E:$E,'บันทึกของเข้า-ออก'!$B:$B,สรุป!$C8,'บันทึกของเข้า-ออก'!$F:$F,สรุป!I$5,'บันทึกของเข้า-ออก'!$D:$D,">="&สรุป!$F$2,'บันทึกของเข้า-ออก'!$D:$D,"<="&สรุป!$G$2) -> 0 | J8: =AC8+SUMIFS('บันทึกของเข้า-ออก'!$J:$J,'บันทึกของเข้า-ออก'!$B:$B,สรุป!$C8,'บันทึกของเข้า-ออก'!$L:$L,สรุป!J$5,'บันทึกของเข้า-ออก'!$I:$I,">="&สรุป!$F$2,'บันทึกของเข้า-ออก'!$I:$I,"<="&สรุป!$G$2)-SUMIFS('บันทึกของเข้า-ออก'!$E:$E,'บันทึกของเข้า-ออก'!$B:$B,สรุป!$C8,'บันทึกของเข้า-ออก'!$F:$F,สรุป!J$5,'บันทึกของเข้า-ออก'!$D:$D,">="&สรุป!$F$2,'บันทึกของเข้า-ออก'!$D:$D,"<="&สรุป!$G$2) -> 0 | K8: =AD8+SUMIFS('บันทึกของเข้า-ออก'!$J:$J,'บันทึกของเข้า-ออก'!$B:$B,สรุป!$C8,'บันทึกของเข้า-ออก'!$L:$L,สรุป!K$5,'บันทึกของเข้า-ออก'!$I:$I,">="&สรุป!$F$2,'บันทึกของเข้า-ออก'!$I:$I,"<="&สรุป!$G$2)-SUMIFS('บันทึกของเข้า-ออก'!$E:$E,'บันทึกของเข้า-ออก'!$B:$B,สรุป!$C8,'บันทึกของเข้า-ออก'!$F:$F,สรุป!K$5,'บันทึกของเข้า-ออก'!$D:$D,">="&สรุป!$F$2,'บันทึกของเข้า-ออก'!$D:$D,"<="&สรุป!$G$2) -> 0 | L8: =AE8+SUMIFS('บันทึกของเข้า-ออก'!$J:$J,'บันทึกของเข้า-ออก'!$B:$B,สรุป!$C8,'บันทึกของเข้า-ออก'!$L:$L,สรุป!L$5,'บันทึกของเข้า-ออก'!$I:$I,">="&สรุป!$F$2,'บันทึกของเข้า-ออก'!$I:$I,"<="&สรุป!$G$2)-SUMIFS('บันทึกของเข้า-ออก'!$E:$E,'บันทึกของเข้า-ออก'!$B:$B,สรุป!$C8,'บันทึกของเข้า-ออก'!$F:$F,สรุป!L$5,'บันทึกของเข้า-ออก'!$D:$D,">="&สรุป!$F$2,'บันทึกของเข้า-ออก'!$D:$D,"<="&สรุป!$G$2) -> 0 | M8: =AF8+SUMIFS('บันทึกของเข้า-ออก'!$J:$J,'บันทึกของเข้า-ออก'!$B:$B,สรุป!$C8,'บันทึกของเข้า-ออก'!$L:$L,สรุป!M$5,'บันทึกของเข้า-ออก'!$I:$I,">="&สรุป!$F$2,'บันทึกของเข้า-ออก'!$I:$I,"<="&สรุป!$G$2)-SUMIFS('บันทึกของเข้า-ออก'!$E:$E,'บันทึกของเข้า-ออก'!$B:$B,สรุป!$C8,'บันทึกของเข้า-ออก'!$F:$F,สรุป!M$5,'บันทึกของเข้า-ออก'!$D:$D,">="&สรุป!$F$2,'บันทึกของเข้า-ออก'!$D:$D,"<="&สรุป!$G$2) -> 0 | ... R8: =AK8+SUMIFS('บันทึกของเข้า-ออก'!$J:$J,'บันทึกของเข้า-ออก'!$B:$B,สรุป!$C8,'บันทึกของเข้า-ออก'!$L:$L,สรุป!R$5,'บันทึกของเข้า-ออก'!$I:$I,">="&สรุป!$F$2,'บันทึกของเข้า-ออก'!$I:$I,"<="&สรุป!$G$2)-SUMIFS('บันทึกของเข้า-ออก'!$E:$E,'บันทึกของเข้า-ออก'!$B:$B,สรุป!$C8,'บันทึกของเข้า-ออก'!$F:$F,สรุป!R$5,'บันทึกของเข้า-ออก'!$D:$D,">="&สรุป!$F$2,'บันทึกของเข้า-ออก'!$D:$D,"<="&สรุป!$G$2) -> 0 | V8: =C8 -> ผ้ากันสะเก็ดไฟ | W8: 2 | X8: ผืน | Y8: 0 | Z8: 0 | AA8: 0 | AB8: 0 | AC8: 0 | AD8: 0 | AE8: 0 | AF8: 0 | AG8: 0 | AH8: 0 | AI8: 0 | AJ8: 0 | AK8: 0
B9: Safety | C9: ถังดับเพลิง | D9: =SUMIF(F9:T9,">0") -> 2 | E9: ถัง | F9: =Y9+SUMIFS('บันทึกของเข้า-ออก'!$J:$J,'บันทึกของเข้า-ออก'!$B:$B,สรุป!$C9,'บันทึกของเข้า-ออก'!$L:$L,สรุป!F$5,'บันทึกของเข้า-ออก'!$I:$I,">="&สรุป!$F$2,'บันทึกของเข้า-ออก'!$I:$I,"<="&สรุป!$G$2)-SUMIFS('บันทึกของเข้า-ออก'!$E:$E,'บันทึกของเข้า-ออก'!$B:$B,สรุป!$C9,'บันทึกของเข้า-ออก'!$F:$F,สรุป!F$5,'บันทึกของเข้า-ออก'!$D:$D,">="&สรุป!$F$2,'บันทึกของเข้า-ออก'!$D:$D,"<="&สรุป!$G$2) -> 0 | G9: 2 | H9: =AA9+SUMIFS('บันทึกของเข้า-ออก'!$J:$J,'บันทึกของเข้า-ออก'!$B:$B,สรุป!$C9,'บันทึกของเข้า-ออก'!$L:$L,สรุป!H$5,'บันทึกของเข้า-ออก'!$I:$I,">="&สรุป!$F$2,'บันทึกของเข้า-ออก'!$I:$I,"<="&สรุป!$G$2)-SUMIFS('บันทึกของเข้า-ออก'!$E:$E,'บันทึกของเข้า-ออก'!$B:$B,สรุป!$C9,'บันทึกของเข้า-ออก'!$F:$F,สรุป!H$5,'บันทึกของเข้า-ออก'!$D:$D,">="&สรุป!$F$2,'บันทึกของเข้า-ออก'!$D:$D,"<="&สรุป!$G$2) -> 0 | I9: =AB9+SUMIFS('บันทึกของเข้า-ออก'!$J:$J,'บันทึกของเข้า-ออก'!$B:$B,สรุป!$C9,'บันทึกของเข้า-ออก'!$L:$L,สรุป!I$5,'บันทึกของเข้า-ออก'!$I:$I,">="&สรุป!$F$2,'บันทึกของเข้า-ออก'!$I:$I,"<="&สรุป!$G$2)-SUMIFS('บันทึกของเข้า-ออก'!$E:$E,'บันทึกของเข้า-ออก'!$B:$B,สรุป!$C9,'บันทึกของเข้า-ออก'!$F:$F,สรุป!I$5,'บันทึกของเข้า-ออก'!$D:$D,">="&สรุป!$F$2,'บันทึกของเข้า-ออก'!$D:$D,"<="&สรุป!$G$2) -> 0 | J9: =AC9+SUMIFS('บันทึกของเข้า-ออก'!$J:$J,'บันทึกของเข้า-ออก'!$B:$B,สรุป!$C9,'บันทึกของเข้า-ออก'!$L:$L,สรุป!J$5,'บันทึกของเข้า-ออก'!$I:$I,">="&สรุป!$F$2,'บันทึกของเข้า-ออก'!$I:$I,"<="&สรุป!$G$2)-SUMIFS('บันทึกของเข้า-ออก'!$E:$E,'บันทึกของเข้า-ออก'!$B:$B,สรุป!$C9,'บันทึกของเข้า-ออก'!$F:$F,สรุป!J$5,'บันทึกของเข้า-ออก'!$D:$D,">="&สรุป!$F$2,'บันทึกของเข้า-ออก'!$D:$D,"<="&สรุป!$G$2) -> 0 | K9: =AD9+SUMIFS('บันทึกของเข้า-ออก'!$J:$J,'บันทึกของเข้า-ออก'!$B:$B,สรุป!$C9,'บันทึกของเข้า-ออก'!$L:$L,สรุป!K$5,'บันทึกของเข้า-ออก'!$I:$I,">="&สรุป!$F$2,'บันทึกของเข้า-ออก'!$I:$I,"<="&สรุป!$G$2)-SUMIFS('บันทึกของเข้า-ออก'!$E:$E,'บันทึกของเข้า-ออก'!$B:$B,สรุป!$C9,'บันทึกของเข้า-ออก'!$F:$F,สรุป!K$5,'บันทึกของเข้า-ออก'!$D:$D,">="&สรุป!$F$2,'บันทึกของเข้า-ออก'!$D:$D,"<="&สรุป!$G$2) -> 0 | L9: =AE9+SUMIFS('บันทึกของเข้า-ออก'!$J:$J,'บันทึกของเข้า-ออก'!$B:$B,สรุป!$C9,'บันทึกของเข้า-ออก'!$L:$L,สรุป!L$5,'บันทึกของเข้า-ออก'!$I:$I,">="&สรุป!$F$2,'บันทึกของเข้า-ออก'!$I:$I,"<="&สรุป!$G$2)-SUMIFS('บันทึกของเข้า-ออก'!$E:$E,'บันทึกของเข้า-ออก'!$B:$B,สรุป!$C9,'บันทึกของเข้า-ออก'!$F:$F,สรุป!L$5,'บันทึกของเข้า-ออก'!$D:$D,">="&สรุป!$F$2,'บันทึกของเข้า-ออก'!$D:$D,"<="&สรุป!$G$2) -> 0 | M9: =AF9+SUMIFS('บันทึกของเข้า-ออก'!$J:$J,'บันทึกของเข้า-ออก'!$B:$B,สรุป!$C9,'บันทึกของเข้า-ออก'!$L:$L,สรุป!M$5,'บันทึกของเข้า-ออก'!$I:$I,">="&สรุป!$F$2,'บันทึกของเข้า-ออก'!$I:$I,"<="&สรุป!$G$2)-SUMIFS('บันทึกของเข้า-ออก'!$E:$E,'บันทึกของเข้า-ออก'!$B:$B,สรุป!$C9,'บันทึกของเข้า-ออก'!$F:$F,สรุป!M$5,'บันทึกของเข้า-ออก'!$D:$D,">="&สรุป!$F$2,'บันทึกของเข้า-ออก'!$D:$D,"<="&สรุป!$G$2) -> 0 | N9: =AG9+SUMIFS('บันทึกของเข้า-ออก'!$J:$J,'บันทึกของเข้า-ออก'!$B:$B,สรุป!$C9,'บันทึกของเข้า-ออก'!$L:$L,สรุป!N$5,'บันทึกของเข้า-ออก'!$I:$I,">="&สรุป!$F$2,'บันทึกของเข้า-ออก'!$I:$I,"<="&สรุป!$G$2)-SUMIFS('บันทึกของเข้า-ออก'!$E:$E,'บันทึกของเข้า-ออก'!$B:$B,สรุป!$C9,'บันทึกของเข้า-ออก'!$F:$F,สรุป!N$5,'บันทึกของเข้า-ออก'!$D:$D,">="&สรุป!$F$2,'บันทึกของเข้า-ออก'!$D:$D,"<="&สรุป!$G$2) -> 0 | O9: =AH9+SUMIFS('บันทึกของเข้า-ออก'!$J:$J,'บันทึกของเข้า-ออก'!$B:$B,สรุป!$C9,'บันทึกของเข้า-ออก'!$L:$L,สรุป!O$5,'บันทึกของเข้า-ออก'!$I:$I,">="&สรุป!$F$2,'บันทึกของเข้า-ออก'!$I:$I,"<="&สรุป!$G$2)-SUMIFS('บันทึกของเข้า-ออก'!$E:$E,'บันทึกของเข้า-ออก'!$B:$B,สรุป!$C9,'บันทึกของเข้า-ออก'!$F:$F,สรุป!O$5,'บันทึกของเข้า-ออก'!$D:$D,">="&สรุป!$F$2,'บันทึกของเข้า-ออก'!$D:$D,"<="&สรุป!$G$2) -> 0 | ... R9: =AK9+SUMIFS('บันทึกของเข้า-ออก'!$J:$J,'บันทึกของเข้า-ออก'!$B:$B,สรุป!$C9,'บันทึกของเข้า-ออก'!$L:$L,สรุป!R$5,'บันทึกของเข้า-ออก'!$I:$I,">="&สรุป!$F$2,'บันทึกของเข้า-ออก'!$I:$I,"<="&สรุป!$G$2)-SUMIFS('บันทึกของเข้า-ออก'!$E:$E,'บันทึกของเข้า-ออก'!$B:$B,สรุป!$C9,'บันทึกของเข้า-ออก'!$F:$F,สรุป!R$5,'บันทึกของเข้า-ออก'!$D:$D,">="&สรุป!$F$2,'บันทึกของเข้า-ออก'!$D:$D,"<="&สรุป!$G$2) -> 0 | V9: =C9 -> ถังดับเพลิง | W9: 4 | X9: ถัง | Y9: 0 | Z9: 2 | AA9: 0 | AB9: 0 | AC9: 0 | AD9: 0 | AE9: 0 | AF9: 0 | AG9: 0 | AH9: 0 | AI9: 0 | AJ9: 0 | AK9: 0
B10: Safety | C10: หมวกเซฟตี้ | D10: =SUMIF(F10:T10,">0") -> 0 | E10: อัน | F10: =Y10+SUMIFS('บันทึกของเข้า-ออก'!$J:$J,'บันทึกของเข้า-ออก'!$B:$B,สรุป!$C10,'บันทึกของเข้า-ออก'!$L:$L,สรุป!F$5,'บันทึกของเข้า-ออก'!$I:$I,">="&สรุป!$F$2,'บันทึกของเข้า-ออก'!$I:$I,"<="&สรุป!$G$2)-SUMIFS('บันทึกของเข้า-ออก'!$E:$E,'บันทึกของเข้า-ออก'!$B:$B,สรุป!$C10,'บันทึกของเข้า-ออก'!$F:$F,สรุป!F$5,'บันทึกของเข้า-ออก'!$D:$D,">="&สรุป!$F$2,'บันทึกของเข้า-ออก'!$D:$D,"<="&สรุป!$G$2) -> 0 | G10: =Z10+SUMIFS('บันทึกของเข้า-ออก'!$J:$J,'บันทึกของเข้า-ออก'!$B:$B,สรุป!$C10,'บันทึกของเข้า-ออก'!$L:$L,สรุป!G$5,'บันทึกของเข้า-ออก'!$I:$I,">="&สรุป!$F$2,'บันทึกของเข้า-ออก'!$I:$I,"<="&สรุป!$G$2)-SUMIFS('บันทึกของเข้า-ออก'!$E:$E,'บันทึกของเข้า-ออก'!$B:$B,สรุป!$C10,'บันทึกของเข้า-ออก'!$F:$F,สรุป!G$5,'บันทึกของเข้า-ออก'!$D:$D,">="&สรุป!$F$2,'บันทึกของเข้า-ออก'!$D:$D,"<="&สรุป!$G$2) -> 0 | H10: =AA10+SUMIFS('บันทึกของเข้า-ออก'!$J:$J,'บันทึกของเข้า-ออก'!$B:$B,สรุป!$C10,'บันทึกของเข้า-ออก'!$L:$L,สรุป!H$5,'บันทึกของเข้า-ออก'!$I:$I,">="&สรุป!$F$2,'บันทึกของเข้า-ออก'!$I:$I,"<="&สรุป!$G$2)-SUMIFS('บันทึกของเข้า-ออก'!$E:$E,'บันทึกของเข้า-ออก'!$B:$B,สรุป!$C10,'บันทึกของเข้า-ออก'!$F:$F,สรุป!H$5,'บันทึกของเข้า-ออก'!$D:$D,">="&สรุป!$F$2,'บันทึกของเข้า-ออก'!$D:$D,"<="&สรุป!$G$2) -> 0 | I10: =AB10+SUMIFS('บันทึกของเข้า-ออก'!$J:$J,'บันทึกของเข้า-ออก'!$B:$B,สรุป!$C10,'บันทึกของเข้า-ออก'!$L:$L,สรุป!I$5,'บันทึกของเข้า-ออก'!$I:$I,">="&สรุป!$F$2,'บันทึกของเข้า-ออก'!$I:$I,"<="&สรุป!$G$2)-SUMIFS('บันทึกของเข้า-ออก'!$E:$E,'บันทึกของเข้า-ออก'!$B:$B,สรุป!$C10,'บันทึกของเข้า-ออก'!$F:$F,สรุป!I$5,'บันทึกของเข้า-ออก'!$D:$D,">="&สรุป!$F$2,'บันทึกของเข้า-ออก'!$D:$D,"<="&สรุป!$G$2) -> 0 | J10: =AC10+SUMIFS('บันทึกของเข้า-ออก'!$J:$J,'บันทึกของเข้า-ออก'!$B:$B,สรุป!$C10,'บันทึกของเข้า-ออก'!$L:$L,สรุป!J$5,'บันทึกของเข้า-ออก'!$I:$I,">="&สรุป!$F$2,'บันทึกของเข้า-ออก'!$I:$I,"<="&สรุป!$G$2)-SUMIFS('บันทึกของเข้า-ออก'!$E:$E,'บันทึกของเข้า-ออก'!$B:$B,สรุป!$C10,'บันทึกของเข้า-ออก'!$F:$F,สรุป!J$5,'บันทึกของเข้า-ออก'!$D:$D,">="&สรุป!$F$2,'บันทึกของเข้า-ออก'!$D:$D,"<="&สรุป!$G$2) -> 0 | K10: =AD10+SUMIFS('บันทึกของเข้า-ออก'!$J:$J,'บันทึกของเข้า-ออก'!$B:$B,สรุป!$C10,'บันทึกของเข้า-ออก'!$L:$L,สรุป!K$5,'บันทึกของเข้า-ออก'!$I:$I,">="&สรุป!$F$2,'บันทึกของเข้า-ออก'!$I:$I,"<="&สรุป!$G$2)-SUMIFS('บันทึกของเข้า-ออก'!$E:$E,'บันทึกของเข้า-ออก'!$B:$B,สรุป!$C10,'บันทึกของเข้า-ออก'!$F:$F,สรุป!K$5,'บันทึกของเข้า-ออก'!$D:$D,">="&สรุป!$F$2,'บันทึกของเข้า-ออก'!$D:$D,"<="&สรุป!$G$2) -> 0 | L10: =AE10+SUMIFS('บันทึกของเข้า-ออก'!$J:$J,'บันทึกของเข้า-ออก'!$B:$B,สรุป!$C10,'บันทึกของเข้า-ออก'!$L:$L,สรุป!L$5,'บันทึกของเข้า-ออก'!$I:$I,">="&สรุป!$F$2,'บันทึกของเข้า-ออก'!$I:$I,"<="&สรุป!$G$2)-SUMIFS('บันทึกของเข้า-ออก'!$E:$E,'บันทึกของเข้า-ออก'!$B:$B,สรุป!$C10,'บันทึกของเข้า-ออก'!$F:$F,สรุป!L$5,'บันทึกของเข้า-ออก'!$D:$D,">="&สรุป!$F$2,'บันทึกของเข้า-ออก'!$D:$D,"<="&สรุป!$G$2) -> 0 | M10: =AF10+SUMIFS('บันทึกของเข้า-ออก'!$J:$J,'บันทึกของเข้า-ออก'!$B:$B,สรุป!$C10,'บันทึกของเข้า-ออก'!$L:$L,สรุป!M$5,'บันทึกของเข้า-ออก'!$I:$I,">="&สรุป!$F$2,'บันทึกของเข้า-ออก'!$I:$I,"<="&สรุป!$G$2)-SUMIFS('บันทึกของเข้า-ออก'!$E:$E,'บันทึกของเข้า-ออก'!$B:$B,สรุป!$C10,'บันทึกของเข้า-ออก'!$F:$F,สรุป!M$5,'บันทึกของเข้า-ออก'!$D:$D,">="&สรุป!$F$2,'บันทึกของเข้า-ออก'!$D:$D,"<="&สรุป!$G$2) -> 0 | ... R10: =AK10+SUMIFS('บันทึกของเข้า-ออก'!$J:$J,'บันทึกของเข้า-ออก'!$B:$B,สรุป!$C10,'บันทึกของเข้า-ออก'!$L:$L,สรุป!R$5,'บันทึกของเข้า-ออก'!$I:$I,">="&สรุป!$F$2,'บันทึกของเข้า-ออก'!$I:$I,"<="&สรุป!$G$2)-SUMIFS('บันทึกของเข้า-ออก'!$E:$E,'บันทึกของเข้า-ออก'!$B:$B,สรุป!$C10,'บันทึกของเข้า-ออก'!$F:$F,สรุป!R$5,'บันทึกของเข้า-ออก'!$D:$D,">="&สรุป!$F$2,'บันทึกของเข้า-ออก'!$D:$D,"<="&สรุป!$G$2) -> 0 | V10: =C10 -> หมวกเซฟตี้ | W10: 18 | X10: อัน | Y10: 0 | Z10: 0 | AA10: 0 | AB10: 0 | AC10: 0 | AD10: 0 | AE10: 0 | AF10: 0 | AG10: 0 | AH10: 0 | AI10: 0 | AJ10: 0 | AK10: 0
B11: Safety | C11: แมสชีส 1.80x5.10 ม. | D11: =SUMIF(F11:T11,">0") -> 223 | E11: ผืน | F11: =Y11+SUMIFS('บันทึกของเข้า-ออก'!$J:$J,'บันทึกของเข้า-ออก'!$B:$B,สรุป!$C11,'บันทึกของเข้า-ออก'!$L:$L,สรุป!F$5,'บันทึกของเข้า-ออก'!$I:$I,">="&สรุป!$F$2,'บันทึกของเข้า-ออก'!$I:$I,"<="&สรุป!$G$2)-SUMIFS('บันทึกของเข้า-ออก'!$E:$E,'บันทึกของเข้า-ออก'!$B:$B,สรุป!$C11,'บันทึกของเข้า-ออก'!$F:$F,สรุป!F$5,'บันทึกของเข้า-ออก'!$D:$D,">="&สรุป!$F$2,'บันทึกของเข้า-ออก'!$D:$D,"<="&สรุป!$G$2) -> 0 | G11: =Z11+SUMIFS('บันทึกของเข้า-ออก'!$J:$J,'บันทึกของเข้า-ออก'!$B:$B,สรุป!$C11,'บันทึกของเข้า-ออก'!$L:$L,สรุป!G$5,'บันทึกของเข้า-ออก'!$I:$I,">="&สรุป!$F$2,'บันทึกของเข้า-ออก'!$I:$I,"<="&สรุป!$G$2)-SUMIFS('บันทึกของเข้า-ออก'!$E:$E,'บันทึกของเข้า-ออก'!$B:$B,สรุป!$C11,'บันทึกของเข้า-ออก'!$F:$F,สรุป!G$5,'บันทึกของเข้า-ออก'!$D:$D,">="&สรุป!$F$2,'บันทึกของเข้า-ออก'!$D:$D,"<="&สรุป!$G$2) -> 40 | H11: =AA11+SUMIFS('บันทึกของเข้า-ออก'!$J:$J,'บันทึกของเข้า-ออก'!$B:$B,สรุป!$C11,'บันทึกของเข้า-ออก'!$L:$L,สรุป!H$5,'บันทึกของเข้า-ออก'!$I:$I,">="&สรุป!$F$2,'บันทึกของเข้า-ออก'!$I:$I,"<="&สรุป!$G$2)-SUMIFS('บันทึกของเข้า-ออก'!$E:$E,'บันทึกของเข้า-ออก'!$B:$B,สรุป!$C11,'บันทึกของเข้า-ออก'!$F:$F,สรุป!H$5,'บันทึกของเข้า-ออก'!$D:$D,">="&สรุป!$F$2,'บันทึกของเข้า-ออก'!$D:$D,"<="&สรุป!$G$2) -> 175 | I11: =AB11+SUMIFS('บันทึกของเข้า-ออก'!$J:$J,'บันทึกของเข้า-ออก'!$B:$B,สรุป!$C11,'บันทึกของเข้า-ออก'!$L:$L,สรุป!I$5,'บันทึกของเข้า-ออก'!$I:$I,">="&สรุป!$F$2,'บันทึกของเข้า-ออก'!$I:$I,"<="&สรุป!$G$2)-SUMIFS('บันทึกของเข้า-ออก'!$E:$E,'บันทึกของเข้า-ออก'!$B:$B,สรุป!$C11,'บันทึกของเข้า-ออก'!$F:$F,สรุป!I$5,'บันทึกของเข้า-ออก'!$D:$D,">="&สรุป!$F$2,'บันทึกของเข้า-ออก'!$D:$D,"<="&สรุป!$G$2) -> 0 | J11: =AC11+SUMIFS('บันทึกของเข้า-ออก'!$J:$J,'บันทึกของเข้า-ออก'!$B:$B,สรุป!$C11,'บันทึกของเข้า-ออก'!$L:$L,สรุป!J$5,'บันทึกของเข้า-ออก'!$I:$I,">="&สรุป!$F$2,'บันทึกของเข้า-ออก'!$I:$I,"<="&สรุป!$G$2)-SUMIFS('บันทึกของเข้า-ออก'!$E:$E,'บันทึกของเข้า-ออก'!$B:$B,สรุป!$C11,'บันทึกของเข้า-ออก'!$F:$F,สรุป!J$5,'บันทึกของเข้า-ออก'!$D:$D,">="&สรุป!$F$2,'บันทึกของเข้า-ออก'!$D:$D,"<="&สรุป!$G$2) -> -18 | K11: =AD11+SUMIFS('บันทึกของเข้า-ออก'!$J:$J,'บันทึกของเข้า-ออก'!$B:$B,สรุป!$C11,'บันทึกของเข้า-ออก'!$L:$L,สรุป!K$5,'บันทึกของเข้า-ออก'!$I:$I,">="&สรุป!$F$2,'บันทึกของเข้า-ออก'!$I:$I,"<="&สรุป!$G$2)-SUMIFS('บันทึกของเข้า-ออก'!$E:$E,'บันทึกของเข้า-ออก'!$B:$B,สรุป!$C11,'บันทึกของเข้า-ออก'!$F:$F,สรุป!K$5,'บันทึกของเข้า-ออก'!$D:$D,">="&สรุป!$F$2,'บันทึกของเข้า-ออก'!$D:$D,"<="&สรุป!$G$2) -> 0 | L11: =AE11+SUMIFS('บันทึกของเข้า-ออก'!$J:$J,'บันทึกของเข้า-ออก'!$B:$B,สรุป!$C11,'บันทึกของเข้า-ออก'!$L:$L,สรุป!L$5,'บันทึกของเข้า-ออก'!$I:$I,">="&สรุป!$F$2,'บันทึกของเข้า-ออก'!$I:$I,"<="&สรุป!$G$2)-SUMIFS('บันทึกของเข้า-ออก'!$E:$E,'บันทึกของเข้า-ออก'!$B:$B,สรุป!$C11,'บันทึกของเข้า-ออก'!$F:$F,สรุป!L$5,'บันทึกของเข้า-ออก'!$D:$D,">="&สรุป!$F$2,'บันทึกของเข้า-ออก'!$D:$D,"<="&สรุป!$G$2) -> 0 | M11: =AF11+SUMIFS('บันทึกของเข้า-ออก'!$J:$J,'บันทึกของเข้า-ออก'!$B:$B,สรุป!$C11,'บันทึกของเข้า-ออก'!$L:$L,สรุป!M$5,'บันทึกของเข้า-ออก'!$I:$I,">="&สรุป!$F$2,'บันทึกของเข้า-ออก'!$I:$I,"<="&สรุป!$G$2)-SUMIFS('บันทึกของเข้า-ออก'!$E:$E,'บันทึกของเข้า-ออก'!$B:$B,สรุป!$C11,'บันทึกของเข้า-ออก'!$F:$F,สรุป!M$5,'บันทึกของเข้า-ออก'!$D:$D,">="&สรุป!$F$2,'บันทึกของเข้า-ออก'!$D:$D,"<="&สรุป!$G$2) -> 0 | ... R11: =AK11+SUMIFS('บันทึกของเข้า-ออก'!$J:$J,'บันทึกของเข้า-ออก'!$B:$B,สรุป!$C11,'บันทึกของเข้า-ออก'!$L:$L,สรุป!R$5,'บันทึกของเข้า-ออก'!$I:$I,">="&สรุป!$F$2,'บันทึกของเข้า-ออก'!$I:$I,"<="&สรุป!$G$2)-SUMIFS('บันทึกของเข้า-ออก'!$E:$E,'บันทึกของเข้า-ออก'!$B:$B,สรุป!$C11,'บันทึกของเข้า-ออก'!$F:$F,สรุป!R$5,'บันทึกของเข้า-ออก'!$D:$D,">="&สรุป!$F$2,'บันทึกของเข้า-ออก'!$D:$D,"<="&สรุป!$G$2) -> 0 | V11: =C11 -> แมสชีส 1.80x5.10 ม. | W11: 205 | X11: ผืน | Y11: 0 | Z11: 40 | AA11: 95 | AB11: 0 | AC11: 70 | AD11: 0 | AE11: 0 | AF11: 0 | AG11: 0 | AH11: 0 | AI11: 0 | AJ11: 0 | AK11: 0
B12: Safety | C12: บลูชีส | D12: =SUMIF(F12:T12,">0") -> 0 | E12: ผืน | F12: =Y12+SUMIFS('บันทึกของเข้า-ออก'!$J:$J,'บันทึกของเข้า-ออก'!$B:$B,สรุป!$C12,'บันทึกของเข้า-ออก'!$L:$L,สรุป!F$5,'บันทึกของเข้า-ออก'!$I:$I,">="&สรุป!$F$2,'บันทึกของเข้า-ออก'!$I:$I,"<="&สรุป!$G$2)-SUMIFS('บันทึกของเข้า-ออก'!$E:$E,'บันทึกของเข้า-ออก'!$B:$B,สรุป!$C12,'บันทึกของเข้า-ออก'!$F:$F,สรุป!F$5,'บันทึกของเข้า-ออก'!$D:$D,">="&สรุป!$F$2,'บันทึกของเข้า-ออก'!$D:$D,"<="&สรุป!$G$2) -> 0 | G12: =Z12+SUMIFS('บันทึกของเข้า-ออก'!$J:$J,'บันทึกของเข้า-ออก'!$B:$B,สรุป!$C12,'บันทึกของเข้า-ออก'!$L:$L,สรุป!G$5,'บันทึกของเข้า-ออก'!$I:$I,">="&สรุป!$F$2,'บันทึกของเข้า-ออก'!$I:$I,"<="&สรุป!$G$2)-SUMIFS('บันทึกของเข้า-ออก'!$E:$E,'บันทึกของเข้า-ออก'!$B:$B,สรุป!$C12,'บันทึกของเข้า-ออก'!$F:$F,สรุป!G$5,'บันทึกของเข้า-ออก'!$D:$D,">="&สรุป!$F$2,'บันทึกของเข้า-ออก'!$D:$D,"<="&สรุป!$G$2) -> 0 | H12: =AA12+SUMIFS('บันทึกของเข้า-ออก'!$J:$J,'บันทึกของเข้า-ออก'!$B:$B,สรุป!$C12,'บันทึกของเข้า-ออก'!$L:$L,สรุป!H$5,'บันทึกของเข้า-ออก'!$I:$I,">="&สรุป!$F$2,'บันทึกของเข้า-ออก'!$I:$I,"<="&สรุป!$G$2)-SUMIFS('บันทึกของเข้า-ออก'!$E:$E,'บันทึกของเข้า-ออก'!$B:$B,สรุป!$C12,'บันทึกของเข้า-ออก'!$F:$F,สรุป!H$5,'บันทึกของเข้า-ออก'!$D:$D,">="&สรุป!$F$2,'บันทึกของเข้า-ออก'!$D:$D,"<="&สรุป!$G$2) -> 0 | I12: =AB12+SUMIFS('บันทึกของเข้า-ออก'!$J:$J,'บันทึกของเข้า-ออก'!$B:$B,สรุป!$C12,'บันทึกของเข้า-ออก'!$L:$L,สรุป!I$5,'บันทึกของเข้า-ออก'!$I:$I,">="&สรุป!$F$2,'บันทึกของเข้า-ออก'!$I:$I,"<="&สรุป!$G$2)-SUMIFS('บันทึกของเข้า-ออก'!$E:$E,'บันทึกของเข้า-ออก'!$B:$B,สรุป!$C12,'บันทึกของเข้า-ออก'!$F:$F,สรุป!I$5,'บันทึกของเข้า-ออก'!$D:$D,">="&สรุป!$F$2,'บันทึกของเข้า-ออก'!$D:$D,"<="&สรุป!$G$2) -> 0 | J12: =AC12+SUMIFS('บันทึกของเข้า-ออก'!$J:$J,'บันทึกของเข้า-ออก'!$B:$B,สรุป!$C12,'บันทึกของเข้า-ออก'!$L:$L,สรุป!J$5,'บันทึกของเข้า-ออก'!$I:$I,">="&สรุป!$F$2,'บันทึกของเข้า-ออก'!$I:$I,"<="&สรุป!$G$2)-SUMIFS('บันทึกของเข้า-ออก'!$E:$E,'บันทึกของเข้า-ออก'!$B:$B,สรุป!$C12,'บันทึกของเข้า-ออก'!$F:$F,สรุป!J$5,'บันทึกของเข้า-ออก'!$D:$D,">="&สรุป!$F$2,'บันทึกของเข้า-ออก'!$D:$D,"<="&สรุป!$G$2) -> 0 | K12: =AD12+SUMIFS('บันทึกของเข้า-ออก'!$J:$J,'บันทึกของเข้า-ออก'!$B:$B,สรุป!$C12,'บันทึกของเข้า-ออก'!$L:$L,สรุป!K$5,'บันทึกของเข้า-ออก'!$I:$I,">="&สรุป!$F$2,'บันทึกของเข้า-ออก'!$I:$I,"<="&สรุป!$G$2)-SUMIFS('บันทึกของเข้า-ออก'!$E:$E,'บันทึกของเข้า-ออก'!$B:$B,สรุป!$C12,'บันทึกของเข้า-ออก'!$F:$F,สรุป!K$5,'บันทึกของเข้า-ออก'!$D:$D,">="&สรุป!$F$2,'บันทึกของเข้า-ออก'!$D:$D,"<="&สรุป!$G$2) -> 0 | L12: =AE12+SUMIFS('บันทึกของเข้า-ออก'!$J:$J,'บันทึกของเข้า-ออก'!$B:$B,สรุป!$C12,'บันทึกของเข้า-ออก'!$L:$L,สรุป!L$5,'บันทึกของเข้า-ออก'!$I:$I,">="&สรุป!$F$2,'บันทึกของเข้า-ออก'!$I:$I,"<="&สรุป!$G$2)-SUMIFS('บันทึกของเข้า-ออก'!$E:$E,'บันทึกของเข้า-ออก'!$B:$B,สรุป!$C12,'บันทึกของเข้า-ออก'!$F:$F,สรุป!L$5,'บันทึกของเข้า-ออก'!$D:$D,">="&สรุป!$F$2,'บันทึกของเข้า-ออก'!$D:$D,"<="&สรุป!$G$2) -> 0 | M12: =AF12+SUMIFS('บันทึกของเข้า-ออก'!$J:$J,'บันทึกของเข้า-ออก'!$B:$B,สรุป!$C12,'บันทึกของเข้า-ออก'!$L:$L,สรุป!M$5,'บันทึกของเข้า-ออก'!$I:$I,">="&สรุป!$F$2,'บันทึกของเข้า-ออก'!$I:$I,"<="&สรุป!$G$2)-SUMIFS('บันทึกของเข้า-ออก'!$E:$E,'บันทึกของเข้า-ออก'!$B:$B,สรุป!$C12,'บันทึกของเข้า-ออก'!$F:$F,สรุป!M$5,'บันทึกของเข้า-ออก'!$D:$D,">="&สรุป!$F$2,'บันทึกของเข้า-ออก'!$D:$D,"<="&สรุป!$G$2) -> 0 | ... R12: =AK12+SUMIFS('บันทึกของเข้า-ออก'!$J:$J,'บันทึกของเข้า-ออก'!$B:$B,สรุป!$C12,'บันทึกของเข้า-ออก'!$L:$L,สรุป!R$5,'บันทึกของเข้า-ออก'!$I:$I,">="&สรุป!$F$2,'บันทึกของเข้า-ออก'!$I:$I,"<="&สรุป!$G$2)-SUMIFS('บันทึกของเข้า-ออก'!$E:$E,'บันทึกของเข้า-ออก'!$B:$B,สรุป!$C12,'บันทึกของเข้า-ออก'!$F:$F,สรุป!R$5,'บันทึกของเข้า-ออก'!$D:$D,">="&สรุป!$F$2,'บันทึกของเข้า-ออก'!$D:$D,"<="&สรุป!$G$2) -> 0 | S12: ข้อมูลไม่ใช่ | V12: =C12 -> บลูชีส | W12: 28 | X12: ผืน | Y12: 0 | Z12: 0 | AA12: 0 | AB12: 0 | AD12: 0 | AE12: 0 | AF12: 0 | AG12: 0 | AH12: 0 | AI12: 0 | AJ12: 0 | AK12: 0
B13: Site | C13: แผ่นเหล็กปูทาง 1.2*2.4 | D13: 5 | E13: แผ่น | F13: =Y13+SUMIFS('บันทึกของเข้า-ออก'!$J:$J,'บันทึกของเข้า-ออก'!$B:$B,สรุป!$C13,'บันทึกของเข้า-ออก'!$L:$L,สรุป!F$5,'บันทึกของเข้า-ออก'!$I:$I,">="&สรุป!$F$2,'บันทึกของเข้า-ออก'!$I:$I,"<="&สรุป!$G$2)-SUMIFS('บันทึกของเข้า-ออก'!$E:$E,'บันทึกของเข้า-ออก'!$B:$B,สรุป!$C13,'บันทึกของเข้า-ออก'!$F:$F,สรุป!F$5,'บันทึกของเข้า-ออก'!$D:$D,">="&สรุป!$F$2,'บันทึกของเข้า-ออก'!$D:$D,"<="&สรุป!$G$2) -> 0 | G13: =Z13+SUMIFS('บันทึกของเข้า-ออก'!$J:$J,'บันทึกของเข้า-ออก'!$B:$B,สรุป!$C13,'บันทึกของเข้า-ออก'!$L:$L,สรุป!G$5,'บันทึกของเข้า-ออก'!$I:$I,">="&สรุป!$F$2,'บันทึกของเข้า-ออก'!$I:$I,"<="&สรุป!$G$2)-SUMIFS('บันทึกของเข้า-ออก'!$E:$E,'บันทึกของเข้า-ออก'!$B:$B,สรุป!$C13,'บันทึกของเข้า-ออก'!$F:$F,สรุป!G$5,'บันทึกของเข้า-ออก'!$D:$D,">="&สรุป!$F$2,'บันทึกของเข้า-ออก'!$D:$D,"<="&สรุป!$G$2) -> 0 | H13: =AA13+SUMIFS('บันทึกของเข้า-ออก'!$J:$J,'บันทึกของเข้า-ออก'!$B:$B,สรุป!$C13,'บันทึกของเข้า-ออก'!$L:$L,สรุป!H$5,'บันทึกของเข้า-ออก'!$I:$I,">="&สรุป!$F$2,'บันทึกของเข้า-ออก'!$I:$I,"<="&สรุป!$G$2)-SUMIFS('บันทึกของเข้า-ออก'!$E:$E,'บันทึกของเข้า-ออก'!$B:$B,สรุป!$C13,'บันทึกของเข้า-ออก'!$F:$F,สรุป!H$5,'บันทึกของเข้า-ออก'!$D:$D,">="&สรุป!$F$2,'บันทึกของเข้า-ออก'!$D:$D,"<="&สรุป!$G$2) -> 0 | I13: =AB13+SUMIFS('บันทึกของเข้า-ออก'!$J:$J,'บันทึกของเข้า-ออก'!$B:$B,สรุป!$C13,'บันทึกของเข้า-ออก'!$L:$L,สรุป!I$5,'บันทึกของเข้า-ออก'!$I:$I,">="&สรุป!$F$2,'บันทึกของเข้า-ออก'!$I:$I,"<="&สรุป!$G$2)-SUMIFS('บันทึกของเข้า-ออก'!$E:$E,'บันทึกของเข้า-ออก'!$B:$B,สรุป!$C13,'บันทึกของเข้า-ออก'!$F:$F,สรุป!I$5,'บันทึกของเข้า-ออก'!$D:$D,">="&สรุป!$F$2,'บันทึกของเข้า-ออก'!$D:$D,"<="&สรุป!$G$2) -> 0 | J13: =AC13+SUMIFS('บันทึกของเข้า-ออก'!$J:$J,'บันทึกของเข้า-ออก'!$B:$B,สรุป!$C13,'บันทึกของเข้า-ออก'!$L:$L,สรุป!J$5,'บันทึกของเข้า-ออก'!$I:$I,">="&สรุป!$F$2,'บันทึกของเข้า-ออก'!$I:$I,"<="&สรุป!$G$2)-SUMIFS('บันทึกของเข้า-ออก'!$E:$E,'บันทึกของเข้า-ออก'!$B:$B,สรุป!$C13,'บันทึกของเข้า-ออก'!$F:$F,สรุป!J$5,'บันทึกของเข้า-ออก'!$D:$D,">="&สรุป!$F$2,'บันทึกของเข้า-ออก'!$D:$D,"<="&สรุป!$G$2) -> 0 | K13: =AD13+SUMIFS('บันทึกของเข้า-ออก'!$J:$J,'บันทึกของเข้า-ออก'!$B:$B,สรุป!$C13,'บันทึกของเข้า-ออก'!$L:$L,สรุป!K$5,'บันทึกของเข้า-ออก'!$I:$I,">="&สรุป!$F$2,'บันทึกของเข้า-ออก'!$I:$I,"<="&สรุป!$G$2)-SUMIFS('บันทึกของเข้า-ออก'!$E:$E,'บันทึกของเข้า-ออก'!$B:$B,สรุป!$C13,'บันทึกของเข้า-ออก'!$F:$F,สรุป!K$5,'บันทึกของเข้า-ออก'!$D:$D,">="&สรุป!$F$2,'บันทึกของเข้า-ออก'!$D:$D,"<="&สรุป!$G$2) -> 0 | L13: =AE13+SUMIFS('บันทึกของเข้า-ออก'!$J:$J,'บันทึกของเข้า-ออก'!$B:$B,สรุป!$C13,'บันทึกของเข้า-ออก'!$L:$L,สรุป!L$5,'บันทึกของเข้า-ออก'!$I:$I,">="&สรุป!$F$2,'บันทึกของเข้า-ออก'!$I:$I,"<="&สรุป!$G$2)-SUMIFS('บันทึกของเข้า-ออก'!$E:$E,'บันทึกของเข้า-ออก'!$B:$B,สรุป!$C13,'บันทึกของเข้า-ออก'!$F:$F,สรุป!L$5,'บันทึกของเข้า-ออก'!$D:$D,">="&สรุป!$F$2,'บันทึกของเข้า-ออก'!$D:$D,"<="&สรุป!$G$2) -> 0 | M13: =AF13+SUMIFS('บันทึกของเข้า-ออก'!$J:$J,'บันทึกของเข้า-ออก'!$B:$B,สรุป!$C13,'บันทึกของเข้า-ออก'!$L:$L,สรุป!M$5,'บันทึกของเข้า-ออก'!$I:$I,">="&สรุป!$F$2,'บันทึกของเข้า-ออก'!$I:$I,"<="&สรุป!$G$2)-SUMIFS('บันทึกของเข้า-ออก'!$E:$E,'บันทึกของเข้า-ออก'!$B:$B,สรุป!$C13,'บันทึกของเข้า-ออก'!$F:$F,สรุป!M$5,'บันทึกของเข้า-ออก'!$D:$D,">="&สรุป!$F$2,'บันทึกของเข้า-ออก'!$D:$D,"<="&สรุป!$G$2) -> 0 | ... R13: =AK13+SUMIFS('บันทึกของเข้า-ออก'!$J:$J,'บันทึกของเข้า-ออก'!$B:$B,สรุป!$C13,'บันทึกของเข้า-ออก'!$L:$L,สรุป!R$5,'บันทึกของเข้า-ออก'!$I:$I,">="&สรุป!$F$2,'บันทึกของเข้า-ออก'!$I:$I,"<="&สรุป!$G$2)-SUMIFS('บันทึกของเข้า-ออก'!$E:$E,'บันทึกของเข้า-ออก'!$B:$B,สรุป!$C13,'บันทึกของเข้า-ออก'!$F:$F,สรุป!R$5,'บันทึกของเข้า-ออก'!$D:$D,">="&สรุป!$F$2,'บันทึกของเข้า-ออก'!$D:$D,"<="&สรุป!$G$2) -> 0 | V13: =C13 -> แผ่นเหล็กปูทาง 1.2*2.4 | W13: 5 | X13: แผ่น | Y13: 0 | Z13: 0 | AA13: 0 | AB13: 0 | AC13: 5 | AD13: 0 | AE13: 0 | AF13: 0 | AG13: 0 | AH13: 0 | AI13: 0 | AJ13: 0 | AK13: 0
B14: Site | C14: ถังน้ำ 200 ลิตร | D14: =SUMIF(F14:T14,">0") -> 9 | E14: ถัง | F14: =Y14+SUMIFS('บันทึกของเข้า-ออก'!$J:$J,'บันทึกของเข้า-ออก'!$B:$B,สรุป!$C14,'บันทึกของเข้า-ออก'!$L:$L,สรุป!F$5,'บันทึกของเข้า-ออก'!$I:$I,">="&สรุป!$F$2,'บันทึกของเข้า-ออก'!$I:$I,"<="&สรุป!$G$2)-SUMIFS('บันทึกของเข้า-ออก'!$E:$E,'บันทึกของเข้า-ออก'!$B:$B,สรุป!$C14,'บันทึกของเข้า-ออก'!$F:$F,สรุป!F$5,'บันทึกของเข้า-ออก'!$D:$D,">="&สรุป!$F$2,'บันทึกของเข้า-ออก'!$D:$D,"<="&สรุป!$G$2) -> 0 | G14: =Z14+SUMIFS('บันทึกของเข้า-ออก'!$J:$J,'บันทึกของเข้า-ออก'!$B:$B,สรุป!$C14,'บันทึกของเข้า-ออก'!$L:$L,สรุป!G$5,'บันทึกของเข้า-ออก'!$I:$I,">="&สรุป!$F$2,'บันทึกของเข้า-ออก'!$I:$I,"<="&สรุป!$G$2)-SUMIFS('บันทึกของเข้า-ออก'!$E:$E,'บันทึกของเข้า-ออก'!$B:$B,สรุป!$C14,'บันทึกของเข้า-ออก'!$F:$F,สรุป!G$5,'บันทึกของเข้า-ออก'!$D:$D,">="&สรุป!$F$2,'บันทึกของเข้า-ออก'!$D:$D,"<="&สรุป!$G$2) -> 1 | H14: =AA14+SUMIFS('บันทึกของเข้า-ออก'!$J:$J,'บันทึกของเข้า-ออก'!$B:$B,สรุป!$C14,'บันทึกของเข้า-ออก'!$L:$L,สรุป!H$5,'บันทึกของเข้า-ออก'!$I:$I,">="&สรุป!$F$2,'บันทึกของเข้า-ออก'!$I:$I,"<="&สรุป!$G$2)-SUMIFS('บันทึกของเข้า-ออก'!$E:$E,'บันทึกของเข้า-ออก'!$B:$B,สรุป!$C14,'บันทึกของเข้า-ออก'!$F:$F,สรุป!H$5,'บันทึกของเข้า-ออก'!$D:$D,">="&สรุป!$F$2,'บันทึกของเข้า-ออก'!$D:$D,"<="&สรุป!$G$2) -> 5 | I14: =AB14+SUMIFS('บันทึกของเข้า-ออก'!$J:$J,'บันทึกของเข้า-ออก'!$B:$B,สรุป!$C14,'บันทึกของเข้า-ออก'!$L:$L,สรุป!I$5,'บันทึกของเข้า-ออก'!$I:$I,">="&สรุป!$F$2,'บันทึกของเข้า-ออก'!$I:$I,"<="&สรุป!$G$2)-SUMIFS('บันทึกของเข้า-ออก'!$E:$E,'บันทึกของเข้า-ออก'!$B:$B,สรุป!$C14,'บันทึกของเข้า-ออก'!$F:$F,สรุป!I$5,'บันทึกของเข้า-ออก'!$D:$D,">="&สรุป!$F$2,'บันทึกของเข้า-ออก'!$D:$D,"<="&สรุป!$G$2) -> 0 | J14: =AC14+SUMIFS('บันทึกของเข้า-ออก'!$J:$J,'บันทึกของเข้า-ออก'!$B:$B,สรุป!$C14,'บันทึกของเข้า-ออก'!$L:$L,สรุป!J$5,'บันทึกของเข้า-ออก'!$I:$I,">="&สรุป!$F$2,'บันทึกของเข้า-ออก'!$I:$I,"<="&สรุป!$G$2)-SUMIFS('บันทึกของเข้า-ออก'!$E:$E,'บันทึกของเข้า-ออก'!$B:$B,สรุป!$C14,'บันทึกของเข้า-ออก'!$F:$F,สรุป!J$5,'บันทึกของเข้า-ออก'!$D:$D,">="&สรุป!$F$2,'บันทึกของเข้า-ออก'!$D:$D,"<="&สรุป!$G$2) -> 0 | K14: =AD14+SUMIFS('บันทึกของเข้า-ออก'!$J:$J,'บันทึกของเข้า-ออก'!$B:$B,สรุป!$C14,'บันทึกของเข้า-ออก'!$L:$L,สรุป!K$5,'บันทึกของเข้า-ออก'!$I:$I,">="&สรุป!$F$2,'บันทึกของเข้า-ออก'!$I:$I,"<="&สรุป!$G$2)-SUMIFS('บันทึกของเข้า-ออก'!$E:$E,'บันทึกของเข้า-ออก'!$B:$B,สรุป!$C14,'บันทึกของเข้า-ออก'!$F:$F,สรุป!K$5,'บันทึกของเข้า-ออก'!$D:$D,">="&สรุป!$F$2,'บันทึกของเข้า-ออก'!$D:$D,"<="&สรุป!$G$2) -> 0 | L14: =AE14+SUMIFS('บันทึกของเข้า-ออก'!$J:$J,'บันทึกของเข้า-ออก'!$B:$B,สรุป!$C14,'บันทึกของเข้า-ออก'!$L:$L,สรุป!L$5,'บันทึกของเข้า-ออก'!$I:$I,">="&สรุป!$F$2,'บันทึกของเข้า-ออก'!$I:$I,"<="&สรุป!$G$2)-SUMIFS('บันทึกของเข้า-ออก'!$E:$E,'บันทึกของเข้า-ออก'!$B:$B,สรุป!$C14,'บันทึกของเข้า-ออก'!$F:$F,สรุป!L$5,'บันทึกของเข้า-ออก'!$D:$D,">="&สรุป!$F$2,'บันทึกของเข้า-ออก'!$D:$D,"<="&สรุป!$G$2) -> 0 | M14: =AF14+SUMIFS('บันทึกของเข้า-ออก'!$J:$J,'บันทึกของเข้า-ออก'!$B:$B,สรุป!$C14,'บันทึกของเข้า-ออก'!$L:$L,สรุป!M$5,'บันทึกของเข้า-ออก'!$I:$I,">="&สรุป!$F$2,'บันทึกของเข้า-ออก'!$I:$I,"<="&สรุป!$G$2)-SUMIFS('บันทึกของเข้า-ออก'!$E:$E,'บันทึกของเข้า-ออก'!$B:$B,สรุป!$C14,'บันทึกของเข้า-ออก'!$F:$F,สรุป!M$5,'บันทึกของเข้า-ออก'!$D:$D,">="&สรุป!$F$2,'บันทึกของเข้า-ออก'!$D:$D,"<="&สรุป!$G$2) -> 2 | ... R14: =AK14+SUMIFS('บันทึกของเข้า-ออก'!$J:$J,'บันทึกของเข้า-ออก'!$B:$B,สรุป!$C14,'บันทึกของเข้า-ออก'!$L:$L,สรุป!R$5,'บันทึกของเข้า-ออก'!$I:$I,">="&สรุป!$F$2,'บันทึกของเข้า-ออก'!$I:$I,"<="&สรุป!$G$2)-SUMIFS('บันทึกของเข้า-ออก'!$E:$E,'บันทึกของเข้า-ออก'!$B:$B,สรุป!$C14,'บันทึกของเข้า-ออก'!$F:$F,สรุป!R$5,'บันทึกของเข้า-ออก'!$D:$D,">="&สรุป!$F$2,'บันทึกของเข้า-ออก'!$D:$D,"<="&สรุป!$G$2) -> 0 | V14: =C14 -> ถังน้ำ 200 ลิตร | W14: 4 | X14: ถัง | Y14: 0 | Z14: 1 | AA14: 5 | AB14: 0 | AC14: 0 | AD14: 0 | AE14: 0 | AF14: 2 | AG14: 0 | AH14: 1 | AI14: 0 | AJ14: 0 | AK14: 0
B15: Site | C15: ถังเก็บน้ำ 500 ลิตร | D15: =SUMIF(F15:T15,">0") -> 2 | E15: ถัง | F15: =Y15+SUMIFS('บันทึกของเข้า-ออก'!$J:$J,'บันทึกของเข้า-ออก'!$B:$B,สรุป!$C15,'บันทึกของเข้า-ออก'!$L:$L,สรุป!F$5,'บันทึกของเข้า-ออก'!$I:$I,">="&สรุป!$F$2,'บันทึกของเข้า-ออก'!$I:$I,"<="&สรุป!$G$2)-SUMIFS('บันทึกของเข้า-ออก'!$E:$E,'บันทึกของเข้า-ออก'!$B:$B,สรุป!$C15,'บันทึกของเข้า-ออก'!$F:$F,สรุป!F$5,'บันทึกของเข้า-ออก'!$D:$D,">="&สรุป!$F$2,'บันทึกของเข้า-ออก'!$D:$D,"<="&สรุป!$G$2) -> 0 | G15: =Z15+SUMIFS('บันทึกของเข้า-ออก'!$J:$J,'บันทึกของเข้า-ออก'!$B:$B,สรุป!$C15,'บันทึกของเข้า-ออก'!$L:$L,สรุป!G$5,'บันทึกของเข้า-ออก'!$I:$I,">="&สรุป!$F$2,'บันทึกของเข้า-ออก'!$I:$I,"<="&สรุป!$G$2)-SUMIFS('บันทึกของเข้า-ออก'!$E:$E,'บันทึกของเข้า-ออก'!$B:$B,สรุป!$C15,'บันทึกของเข้า-ออก'!$F:$F,สรุป!G$5,'บันทึกของเข้า-ออก'!$D:$D,">="&สรุป!$F$2,'บันทึกของเข้า-ออก'!$D:$D,"<="&สรุป!$G$2) -> 0 | H15: =AA15+SUMIFS('บันทึกของเข้า-ออก'!$J:$J,'บันทึกของเข้า-ออก'!$B:$B,สรุป!$C15,'บันทึกของเข้า-ออก'!$L:$L,สรุป!H$5,'บันทึกของเข้า-ออก'!$I:$I,">="&สรุป!$F$2,'บันทึกของเข้า-ออก'!$I:$I,"<="&สรุป!$G$2)-SUMIFS('บันทึกของเข้า-ออก'!$E:$E,'บันทึกของเข้า-ออก'!$B:$B,สรุป!$C15,'บันทึกของเข้า-ออก'!$F:$F,สรุป!H$5,'บันทึกของเข้า-ออก'!$D:$D,">="&สรุป!$F$2,'บันทึกของเข้า-ออก'!$D:$D,"<="&สรุป!$G$2) -> 2 | I15: =AB15+SUMIFS('บันทึกของเข้า-ออก'!$J:$J,'บันทึกของเข้า-ออก'!$B:$B,สรุป!$C15,'บันทึกของเข้า-ออก'!$L:$L,สรุป!I$5,'บันทึกของเข้า-ออก'!$I:$I,">="&สรุป!$F$2,'บันทึกของเข้า-ออก'!$I:$I,"<="&สรุป!$G$2)-SUMIFS('บันทึกของเข้า-ออก'!$E:$E,'บันทึกของเข้า-ออก'!$B:$B,สรุป!$C15,'บันทึกของเข้า-ออก'!$F:$F,สรุป!I$5,'บันทึกของเข้า-ออก'!$D:$D,">="&สรุป!$F$2,'บันทึกของเข้า-ออก'!$D:$D,"<="&สรุป!$G$2) -> 0 | J15: =AC15+SUMIFS('บันทึกของเข้า-ออก'!$J:$J,'บันทึกของเข้า-ออก'!$B:$B,สรุป!$C15,'บันทึกของเข้า-ออก'!$L:$L,สรุป!J$5,'บันทึกของเข้า-ออก'!$I:$I,">="&สรุป!$F$2,'บันทึกของเข้า-ออก'!$I:$I,"<="&สรุป!$G$2)-SUMIFS('บันทึกของเข้า-ออก'!$E:$E,'บันทึกของเข้า-ออก'!$B:$B,สรุป!$C15,'บันทึกของเข้า-ออก'!$F:$F,สรุป!J$5,'บันทึกของเข้า-ออก'!$D:$D,">="&สรุป!$F$2,'บันทึกของเข้า-ออก'!$D:$D,"<="&สรุป!$G$2) -> 0 | K15: =AD15+SUMIFS('บันทึกของเข้า-ออก'!$J:$J,'บันทึกของเข้า-ออก'!$B:$B,สรุป!$C15,'บันทึกของเข้า-ออก'!$L:$L,สรุป!K$5,'บันทึกของเข้า-ออก'!$I:$I,">="&สรุป!$F$2,'บันทึกของเข้า-ออก'!$I:$I,"<="&สรุป!$G$2)-SUMIFS('บันทึกของเข้า-ออก'!$E:$E,'บันทึกของเข้า-ออก'!$B:$B,สรุป!$C15,'บันทึกของเข้า-ออก'!$F:$F,สรุป!K$5,'บันทึกของเข้า-ออก'!$D:$D,">="&สรุป!$F$2,'บันทึกของเข้า-ออก'!$D:$D,"<="&สรุป!$G$2) -> 0 | L15: =AE15+SUMIFS('บันทึกของเข้า-ออก'!$J:$J,'บันทึกของเข้า-ออก'!$B:$B,สรุป!$C15,'บันทึกของเข้า-ออก'!$L:$L,สรุป!L$5,'บันทึกของเข้า-ออก'!$I:$I,">="&สรุป!$F$2,'บันทึกของเข้า-ออก'!$I:$I,"<="&สรุป!$G$2)-SUMIFS('บันทึกของเข้า-ออก'!$E:$E,'บันทึกของเข้า-ออก'!$B:$B,สรุป!$C15,'บันทึกของเข้า-ออก'!$F:$F,สรุป!L$5,'บันทึกของเข้า-ออก'!$D:$D,">="&สรุป!$F$2,'บันทึกของเข้า-ออก'!$D:$D,"<="&สรุป!$G$2) -> 0 | M15: =AF15+SUMIFS('บันทึกของเข้า-ออก'!$J:$J,'บันทึกของเข้า-ออก'!$B:$B,สรุป!$C15,'บันทึกของเข้า-ออก'!$L:$L,สรุป!M$5,'บันทึกของเข้า-ออก'!$I:$I,">="&สรุป!$F$2,'บันทึกของเข้า-ออก'!$I:$I,"<="&สรุป!$G$2)-SUMIFS('บันทึกของเข้า-ออก'!$E:$E,'บันทึกของเข้า-ออก'!$B:$B,สรุป!$C15,'บันทึกของเข้า-ออก'!$F:$F,สรุป!M$5,'บันทึกของเข้า-ออก'!$D:$D,">="&สรุป!$F$2,'บันทึกของเข้า-ออก'!$D:$D,"<="&สรุป!$G$2) -> 0 | ... R15: =AK15+SUMIFS('บันทึกของเข้า-ออก'!$J:$J,'บันทึกของเข้า-ออก'!$B:$B,สรุป!$C15,'บันทึกของเข้า-ออก'!$L:$L,สรุป!R$5,'บันทึกของเข้า-ออก'!$I:$I,">="&สรุป!$F$2,'บันทึกของเข้า-ออก'!$I:$I,"<="&สรุป!$G$2)-SUMIFS('บันทึกของเข้า-ออก'!$E:$E,'บันทึกของเข้า-ออก'!$B:$B,สรุป!$C15,'บันทึกของเข้า-ออก'!$F:$F,สรุป!R$5,'บันทึกของเข้า-ออก'!$D:$D,">="&สรุป!$F$2,'บันทึกของเข้า-ออก'!$D:$D,"<="&สรุป!$G$2) -> 0 | V15: =C15 -> ถังเก็บน้ำ 500 ลิตร | W15: 1 | X15: ถัง | Y15: 0 | Z15: 0 | AA15: 2 | AB15: 0 | AC15: 0 | AD15: 0 | AE15: 0 | AF15: 0 | AG15: 0 | AH15: 0 | AI15: 0 | AJ15: 0 | AK15: 0
B16: Site | C16: ถังเก็บน้ำ 1000 ลิตร | D16: =SUMIF(F16:T16,">0") -> 7 | E16: ถัง | F16: =Y16+SUMIFS('บันทึกของเข้า-ออก'!$J:$J,'บันทึกของเข้า-ออก'!$B:$B,สรุป!$C16,'บันทึกของเข้า-ออก'!$L:$L,สรุป!F$5,'บันทึกของเข้า-ออก'!$I:$I,">="&สรุป!$F$2,'บันทึกของเข้า-ออก'!$I:$I,"<="&สรุป!$G$2)-SUMIFS('บันทึกของเข้า-ออก'!$E:$E,'บันทึกของเข้า-ออก'!$B:$B,สรุป!$C16,'บันทึกของเข้า-ออก'!$F:$F,สรุป!F$5,'บันทึกของเข้า-ออก'!$D:$D,">="&สรุป!$F$2,'บันทึกของเข้า-ออก'!$D:$D,"<="&สรุป!$G$2) -> 0 | G16: =Z16+SUMIFS('บันทึกของเข้า-ออก'!$J:$J,'บันทึกของเข้า-ออก'!$B:$B,สรุป!$C16,'บันทึกของเข้า-ออก'!$L:$L,สรุป!G$5,'บันทึกของเข้า-ออก'!$I:$I,">="&สรุป!$F$2,'บันทึกของเข้า-ออก'!$I:$I,"<="&สรุป!$G$2)-SUMIFS('บันทึกของเข้า-ออก'!$E:$E,'บันทึกของเข้า-ออก'!$B:$B,สรุป!$C16,'บันทึกของเข้า-ออก'!$F:$F,สรุป!G$5,'บันทึกของเข้า-ออก'!$D:$D,">="&สรุป!$F$2,'บันทึกของเข้า-ออก'!$D:$D,"<="&สรุป!$G$2) -> 0 | H16: =AA16+SUMIFS('บันทึกของเข้า-ออก'!$J:$J,'บันทึกของเข้า-ออก'!$B:$B,สรุป!$C16,'บันทึกของเข้า-ออก'!$L:$L,สรุป!H$5,'บันทึกของเข้า-ออก'!$I:$I,">="&สรุป!$F$2,'บันทึกของเข้า-ออก'!$I:$I,"<="&สรุป!$G$2)-SUMIFS('บันทึกของเข้า-ออก'!$E:$E,'บันทึกของเข้า-ออก'!$B:$B,สรุป!$C16,'บันทึกของเข้า-ออก'!$F:$F,สรุป!H$5,'บันทึกของเข้า-ออก'!$D:$D,">="&สรุป!$F$2,'บันทึกของเข้า-ออก'!$D:$D,"<="&สรุป!$G$2) -> 1 | I16: =AB16+SUMIFS('บันทึกของเข้า-ออก'!$J:$J,'บันทึกของเข้า-ออก'!$B:$B,สรุป!$C16,'บันทึกของเข้า-ออก'!$L:$L,สรุป!I$5,'บันทึกของเข้า-ออก'!$I:$I,">="&สรุป!$F$2,'บันทึกของเข้า-ออก'!$I:$I,"<="&สรุป!$G$2)-SUMIFS('บันทึกของเข้า-ออก'!$E:$E,'บันทึกของเข้า-ออก'!$B:$B,สรุป!$C16,'บันทึกของเข้า-ออก'!$F:$F,สรุป!I$5,'บันทึกของเข้า-ออก'!$D:$D,">="&สรุป!$F$2,'บันทึกของเข้า-ออก'!$D:$D,"<="&สรุป!$G$2) -> 0 | J16: =AC16+SUMIFS('บันทึกของเข้า-ออก'!$J:$J,'บันทึกของเข้า-ออก'!$B:$B,สรุป!$C16,'บันทึกของเข้า-ออก'!$L:$L,สรุป!J$5,'บันทึกของเข้า-ออก'!$I:$I,">="&สรุป!$F$2,'บันทึกของเข้า-ออก'!$I:$I,"<="&สรุป!$G$2)-SUMIFS('บันทึกของเข้า-ออก'!$E:$E,'บันทึกของเข้า-ออก'!$B:$B,สรุป!$C16,'บันทึกของเข้า-ออก'!$F:$F,สรุป!J$5,'บันทึกของเข้า-ออก'!$D:$D,">="&สรุป!$F$2,'บันทึกของเข้า-ออก'!$D:$D,"<="&สรุป!$G$2) -> 1 | K16: =AD16+SUMIFS('บันทึกของเข้า-ออก'!$J:$J,'บันทึกของเข้า-ออก'!$B:$B,สรุป!$C16,'บันทึกของเข้า-ออก'!$L:$L,สรุป!K$5,'บันทึกของเข้า-ออก'!$I:$I,">="&สรุป!$F$2,'บันทึกของเข้า-ออก'!$I:$I,"<="&สรุป!$G$2)-SUMIFS('บันทึกของเข้า-ออก'!$E:$E,'บันทึกของเข้า-ออก'!$B:$B,สรุป!$C16,'บันทึกของเข้า-ออก'!$F:$F,สรุป!K$5,'บันทึกของเข้า-ออก'!$D:$D,">="&สรุป!$F$2,'บันทึกของเข้า-ออก'!$D:$D,"<="&สรุป!$G$2) -> 0 | L16: =AE16+SUMIFS('บันทึกของเข้า-ออก'!$J:$J,'บันทึกของเข้า-ออก'!$B:$B,สรุป!$C16,'บันทึกของเข้า-ออก'!$L:$L,สรุป!L$5,'บันทึกของเข้า-ออก'!$I:$I,">="&สรุป!$F$2,'บันทึกของเข้า-ออก'!$I:$I,"<="&สรุป!$G$2)-SUMIFS('บันทึกของเข้า-ออก'!$E:$E,'บันทึกของเข้า-ออก'!$B:$B,สรุป!$C16,'บันทึกของเข้า-ออก'!$F:$F,สรุป!L$5,'บันทึกของเข้า-ออก'!$D:$D,">="&สรุป!$F$2,'บันทึกของเข้า-ออก'!$D:$D,"<="&สรุป!$G$2) -> 0 | M16: =AF16+SUMIFS('บันทึกของเข้า-ออก'!$J:$J,'บันทึกของเข้า-ออก'!$B:$B,สรุป!$C16,'บันทึกของเข้า-ออก'!$L:$L,สรุป!M$5,'บันทึกของเข้า-ออก'!$I:$I,">="&สรุป!$F$2,'บันทึกของเข้า-ออก'!$I:$I,"<="&สรุป!$G$2)-SUMIFS('บันทึกของเข้า-ออก'!$E:$E,'บันทึกของเข้า-ออก'!$B:$B,สรุป!$C16,'บันทึกของเข้า-ออก'!$F:$F,สรุป!M$5,'บันทึกของเข้า-ออก'!$D:$D,">="&สรุป!$F$2,'บันทึกของเข้า-ออก'!$D:$D,"<="&สรุป!$G$2) -> 4 | ... R16: =AK16+SUMIFS('บันทึกของเข้า-ออก'!$J:$J,'บันทึกของเข้า-ออก'!$B:$B,สรุป!$C16,'บันทึกของเข้า-ออก'!$L:$L,สรุป!R$5,'บันทึกของเข้า-ออก'!$I:$I,">="&สรุป!$F$2,'บันทึกของเข้า-ออก'!$I:$I,"<="&สรุป!$G$2)-SUMIFS('บันทึกของเข้า-ออก'!$E:$E,'บันทึกของเข้า-ออก'!$B:$B,สรุป!$C16,'บันทึกของเข้า-ออก'!$F:$F,สรุป!R$5,'บันทึกของเข้า-ออก'!$D:$D,">="&สรุป!$F$2,'บันทึกของเข้า-ออก'!$D:$D,"<="&สรุป!$G$2) -> 0 | V16: =C16 -> ถังเก็บน้ำ 1000 ลิตร | W16: 6 | X16: ถัง | Y16: 0 | Z16: 0 | AA16: 1 | AB16: 0 | AC16: 1 | AD16: 0 | AE16: 0 | AF16: 4 | AG16: 0 | AH16: 1 | AI16: 0 | AJ16: 0 | AK16: 0
B17: Site | C17: ถังเก็บน้ำ 2000 ลิตร | D17: =SUMIF(F17:T17,">0") -> 0 | E17: ถัง | F17: =Y17+SUMIFS('บันทึกของเข้า-ออก'!$J:$J,'บันทึกของเข้า-ออก'!$B:$B,สรุป!$C17,'บันทึกของเข้า-ออก'!$L:$L,สรุป!F$5,'บันทึกของเข้า-ออก'!$I:$I,">="&สรุป!$F$2,'บันทึกของเข้า-ออก'!$I:$I,"<="&สรุป!$G$2)-SUMIFS('บันทึกของเข้า-ออก'!$E:$E,'บันทึกของเข้า-ออก'!$B:$B,สรุป!$C17,'บันทึกของเข้า-ออก'!$F:$F,สรุป!F$5,'บันทึกของเข้า-ออก'!$D:$D,">="&สรุป!$F$2,'บันทึกของเข้า-ออก'!$D:$D,"<="&สรุป!$G$2) -> 0 | G17: =Z17+SUMIFS('บันทึกของเข้า-ออก'!$J:$J,'บันทึกของเข้า-ออก'!$B:$B,สรุป!$C17,'บันทึกของเข้า-ออก'!$L:$L,สรุป!G$5,'บันทึกของเข้า-ออก'!$I:$I,">="&สรุป!$F$2,'บันทึกของเข้า-ออก'!$I:$I,"<="&สรุป!$G$2)-SUMIFS('บันทึกของเข้า-ออก'!$E:$E,'บันทึกของเข้า-ออก'!$B:$B,สรุป!$C17,'บันทึกของเข้า-ออก'!$F:$F,สรุป!G$5,'บันทึกของเข้า-ออก'!$D:$D,">="&สรุป!$F$2,'บันทึกของเข้า-ออก'!$D:$D,"<="&สรุป!$G$2) -> 0 | H17: =AA17+SUMIFS('บันทึกของเข้า-ออก'!$J:$J,'บันทึกของเข้า-ออก'!$B:$B,สรุป!$C17,'บันทึกของเข้า-ออก'!$L:$L,สรุป!H$5,'บันทึกของเข้า-ออก'!$I:$I,">="&สรุป!$F$2,'บันทึกของเข้า-ออก'!$I:$I,"<="&สรุป!$G$2)-SUMIFS('บันทึกของเข้า-ออก'!$E:$E,'บันทึกของเข้า-ออก'!$B:$B,สรุป!$C17,'บันทึกของเข้า-ออก'!$F:$F,สรุป!H$5,'บันทึกของเข้า-ออก'!$D:$D,">="&สรุป!$F$2,'บันทึกของเข้า-ออก'!$D:$D,"<="&สรุป!$G$2) -> 0 | I17: =AB17+SUMIFS('บันทึกของเข้า-ออก'!$J:$J,'บันทึกของเข้า-ออก'!$B:$B,สรุป!$C17,'บันทึกของเข้า-ออก'!$L:$L,สรุป!I$5,'บันทึกของเข้า-ออก'!$I:$I,">="&สรุป!$F$2,'บันทึกของเข้า-ออก'!$I:$I,"<="&สรุป!$G$2)-SUMIFS('บันทึกของเข้า-ออก'!$E:$E,'บันทึกของเข้า-ออก'!$B:$B,สรุป!$C17,'บันทึกของเข้า-ออก'!$F:$F,สรุป!I$5,'บันทึกของเข้า-ออก'!$D:$D,">="&สรุป!$F$2,'บันทึกของเข้า-ออก'!$D:$D,"<="&สรุป!$G$2) -> 0 | J17: =AC17+SUMIFS('บันทึกของเข้า-ออก'!$J:$J,'บันทึกของเข้า-ออก'!$B:$B,สรุป!$C17,'บันทึกของเข้า-ออก'!$L:$L,สรุป!J$5,'บันทึกของเข้า-ออก'!$I:$I,">="&สรุป!$F$2,'บันทึกของเข้า-ออก'!$I:$I,"<="&สรุป!$G$2)-SUMIFS('บันทึกของเข้า-ออก'!$E:$E,'บันทึกของเข้า-ออก'!$B:$B,สรุป!$C17,'บันทึกของเข้า-ออก'!$F:$F,สรุป!J$5,'บันทึกของเข้า-ออก'!$D:$D,">="&สรุป!$F$2,'บันทึกของเข้า-ออก'!$D:$D,"<="&สรุป!$G$2) -> 0 | K17: =AD17+SUMIFS('บันทึกของเข้า-ออก'!$J:$J,'บันทึกของเข้า-ออก'!$B:$B,สรุป!$C17,'บันทึกของเข้า-ออก'!$L:$L,สรุป!K$5,'บันทึกของเข้า-ออก'!$I:$I,">="&สรุป!$F$2,'บันทึกของเข้า-ออก'!$I:$I,"<="&สรุป!$G$2)-SUMIFS('บันทึกของเข้า-ออก'!$E:$E,'บันทึกของเข้า-ออก'!$B:$B,สรุป!$C17,'บันทึกของเข้า-ออก'!$F:$F,สรุป!K$5,'บันทึกของเข้า-ออก'!$D:$D,">="&สรุป!$F$2,'บันทึกของเข้า-ออก'!$D:$D,"<="&สรุป!$G$2) -> 0 | L17: =AE17+SUMIFS('บันทึกของเข้า-ออก'!$J:$J,'บันทึกของเข้า-ออก'!$B:$B,สรุป!$C17,'บันทึกของเข้า-ออก'!$L:$L,สรุป!L$5,'บันทึกของเข้า-ออก'!$I:$I,">="&สรุป!$F$2,'บันทึกของเข้า-ออก'!$I:$I,"<="&สรุป!$G$2)-SUMIFS('บันทึกของเข้า-ออก'!$E:$E,'บันทึกของเข้า-ออก'!$B:$B,สรุป!$C17,'บันทึกของเข้า-ออก'!$F:$F,สรุป!L$5,'บันทึกของเข้า-ออก'!$D:$D,">="&สรุป!$F$2,'บันทึกของเข้า-ออก'!$D:$D,"<="&สรุป!$G$2) -> 0 | M17: =AF17+SUMIFS('บันทึกของเข้า-ออก'!$J:$J,'บันทึกของเข้า-ออก'!$B:$B,สรุป!$C17,'บันทึกของเข้า-ออก'!$L:$L,สรุป!M$5,'บันทึกของเข้า-ออก'!$I:$I,">="&สรุป!$F$2,'บันทึกของเข้า-ออก'!$I:$I,"<="&สรุป!$G$2)-SUMIFS('บันทึกของเข้า-ออก'!$E:$E,'บันทึกของเข้า-ออก'!$B:$B,สรุป!$C17,'บันทึกของเข้า-ออก'!$F:$F,สรุป!M$5,'บันทึกของเข้า-ออก'!$D:$D,">="&สรุป!$F$2,'บันทึกของเข้า-ออก'!$D:$D,"<="&สรุป!$G$2) -> 0 | ... R17: =AK17+SUMIFS('บันทึกของเข้า-ออก'!$J:$J,'บันทึกของเข้า-ออก'!$B:$B,สรุป!$C17,'บันทึกของเข้า-ออก'!$L:$L,สรุป!R$5,'บันทึกของเข้า-ออก'!$I:$I,">="&สรุป!$F$2,'บันทึกของเข้า-ออก'!$I:$I,"<="&สรุป!$G$2)-SUMIFS('บันทึกของเข้า-ออก'!$E:$E,'บันทึกของเข้า-ออก'!$B:$B,สรุป!$C17,'บันทึกของเข้า-ออก'!$F:$F,สรุป!R$5,'บันทึกของเข้า-ออก'!$D:$D,">="&สรุป!$F$2,'บันทึกของเข้า-ออก'!$D:$D,"<="&สรุป!$G$2) -> 0 | V17: =C17 -> ถังเก็บน้ำ 2000 ลิตร | W17: 0 | X17: ถัง | Y17: 0 | Z17: 0 | AA17: 0 | AB17: 0 | AC17: 0 | AD17: 0 | AE17: 0 | AF17: 0 | AG17: 0 | AH17: 0 | AI17: 0 | AJ17: 0 | AK17: 0
B18: Site | C18: ห้องน้ำสนาม | D18: =SUMIF(F18:T18,">0") -> 1 | E18: ห้อง | F18: =Y18+SUMIFS('บันทึกของเข้า-ออก'!$J:$J,'บันทึกของเข้า-ออก'!$B:$B,สรุป!$C18,'บันทึกของเข้า-ออก'!$L:$L,สรุป!F$5,'บันทึกของเข้า-ออก'!$I:$I,">="&สรุป!$F$2,'บันทึกของเข้า-ออก'!$I:$I,"<="&สรุป!$G$2)-SUMIFS('บันทึกของเข้า-ออก'!$E:$E,'บันทึกของเข้า-ออก'!$B:$B,สรุป!$C18,'บันทึกของเข้า-ออก'!$F:$F,สรุป!F$5,'บันทึกของเข้า-ออก'!$D:$D,">="&สรุป!$F$2,'บันทึกของเข้า-ออก'!$D:$D,"<="&สรุป!$G$2) -> 0 | G18: =Z18+SUMIFS('บันทึกของเข้า-ออก'!$J:$J,'บันทึกของเข้า-ออก'!$B:$B,สรุป!$C18,'บันทึกของเข้า-ออก'!$L:$L,สรุป!G$5,'บันทึกของเข้า-ออก'!$I:$I,">="&สรุป!$F$2,'บันทึกของเข้า-ออก'!$I:$I,"<="&สรุป!$G$2)-SUMIFS('บันทึกของเข้า-ออก'!$E:$E,'บันทึกของเข้า-ออก'!$B:$B,สรุป!$C18,'บันทึกของเข้า-ออก'!$F:$F,สรุป!G$5,'บันทึกของเข้า-ออก'!$D:$D,">="&สรุป!$F$2,'บันทึกของเข้า-ออก'!$D:$D,"<="&สรุป!$G$2) -> 0 | H18: =AA18+SUMIFS('บันทึกของเข้า-ออก'!$J:$J,'บันทึกของเข้า-ออก'!$B:$B,สรุป!$C18,'บันทึกของเข้า-ออก'!$L:$L,สรุป!H$5,'บันทึกของเข้า-ออก'!$I:$I,">="&สรุป!$F$2,'บันทึกของเข้า-ออก'!$I:$I,"<="&สรุป!$G$2)-SUMIFS('บันทึกของเข้า-ออก'!$E:$E,'บันทึกของเข้า-ออก'!$B:$B,สรุป!$C18,'บันทึกของเข้า-ออก'!$F:$F,สรุป!H$5,'บันทึกของเข้า-ออก'!$D:$D,">="&สรุป!$F$2,'บันทึกของเข้า-ออก'!$D:$D,"<="&สรุป!$G$2) -> 0 | I18: =AB18+SUMIFS('บันทึกของเข้า-ออก'!$J:$J,'บันทึกของเข้า-ออก'!$B:$B,สรุป!$C18,'บันทึกของเข้า-ออก'!$L:$L,สรุป!I$5,'บันทึกของเข้า-ออก'!$I:$I,">="&สรุป!$F$2,'บันทึกของเข้า-ออก'!$I:$I,"<="&สรุป!$G$2)-SUMIFS('บันทึกของเข้า-ออก'!$E:$E,'บันทึกของเข้า-ออก'!$B:$B,สรุป!$C18,'บันทึกของเข้า-ออก'!$F:$F,สรุป!I$5,'บันทึกของเข้า-ออก'!$D:$D,">="&สรุป!$F$2,'บันทึกของเข้า-ออก'!$D:$D,"<="&สรุป!$G$2) -> 0 | J18: =AC18+SUMIFS('บันทึกของเข้า-ออก'!$J:$J,'บันทึกของเข้า-ออก'!$B:$B,สรุป!$C18,'บันทึกของเข้า-ออก'!$L:$L,สรุป!J$5,'บันทึกของเข้า-ออก'!$I:$I,">="&สรุป!$F$2,'บันทึกของเข้า-ออก'!$I:$I,"<="&สรุป!$G$2)-SUMIFS('บันทึกของเข้า-ออก'!$E:$E,'บันทึกของเข้า-ออก'!$B:$B,สรุป!$C18,'บันทึกของเข้า-ออก'!$F:$F,สรุป!J$5,'บันทึกของเข้า-ออก'!$D:$D,">="&สรุป!$F$2,'บันทึกของเข้า-ออก'!$D:$D,"<="&สรุป!$G$2) -> 0 | K18: =AD18+SUMIFS('บันทึกของเข้า-ออก'!$J:$J,'บันทึกของเข้า-ออก'!$B:$B,สรุป!$C18,'บันทึกของเข้า-ออก'!$L:$L,สรุป!K$5,'บันทึกของเข้า-ออก'!$I:$I,">="&สรุป!$F$2,'บันทึกของเข้า-ออก'!$I:$I,"<="&สรุป!$G$2)-SUMIFS('บันทึกของเข้า-ออก'!$E:$E,'บันทึกของเข้า-ออก'!$B:$B,สรุป!$C18,'บันทึกของเข้า-ออก'!$F:$F,สรุป!K$5,'บันทึกของเข้า-ออก'!$D:$D,">="&สรุป!$F$2,'บันทึกของเข้า-ออก'!$D:$D,"<="&สรุป!$G$2) -> 0 | L18: =AE18+SUMIFS('บันทึกของเข้า-ออก'!$J:$J,'บันทึกของเข้า-ออก'!$B:$B,สรุป!$C18,'บันทึกของเข้า-ออก'!$L:$L,สรุป!L$5,'บันทึกของเข้า-ออก'!$I:$I,">="&สรุป!$F$2,'บันทึกของเข้า-ออก'!$I:$I,"<="&สรุป!$G$2)-SUMIFS('บันทึกของเข้า-ออก'!$E:$E,'บันทึกของเข้า-ออก'!$B:$B,สรุป!$C18,'บันทึกของเข้า-ออก'!$F:$F,สรุป!L$5,'บันทึกของเข้า-ออก'!$D:$D,">="&สรุป!$F$2,'บันทึกของเข้า-ออก'!$D:$D,"<="&สรุป!$G$2) -> 0 | M18: =AF18+SUMIFS('บันทึกของเข้า-ออก'!$J:$J,'บันทึกของเข้า-ออก'!$B:$B,สรุป!$C18,'บันทึกของเข้า-ออก'!$L:$L,สรุป!M$5,'บันทึกของเข้า-ออก'!$I:$I,">="&สรุป!$F$2,'บันทึกของเข้า-ออก'!$I:$I,"<="&สรุป!$G$2)-SUMIFS('บันทึกของเข้า-ออก'!$E:$E,'บันทึกของเข้า-ออก'!$B:$B,สรุป!$C18,'บันทึกของเข้า-ออก'!$F:$F,สรุป!M$5,'บันทึกของเข้า-ออก'!$D:$D,">="&สรุป!$F$2,'บันทึกของเข้า-ออก'!$D:$D,"<="&สรุป!$G$2) -> 1 | ... R18: =AK18+SUMIFS('บันทึกของเข้า-ออก'!$J:$J,'บันทึกของเข้า-ออก'!$B:$B,สรุป!$C18,'บันทึกของเข้า-ออก'!$L:$L,สรุป!R$5,'บันทึกของเข้า-ออก'!$I:$I,">="&สรุป!$F$2,'บันทึกของเข้า-ออก'!$I:$I,"<="&สรุป!$G$2)-SUMIFS('บันทึกของเข้า-ออก'!$E:$E,'บันทึกของเข้า-ออก'!$B:$B,สรุป!$C18,'บันทึกของเข้า-ออก'!$F:$F,สรุป!R$5,'บันทึกของเข้า-ออก'!$D:$D,">="&สรุป!$F$2,'บันทึกของเข้า-ออก'!$D:$D,"<="&สรุป!$G$2) -> 0 | V18: =C18 -> ห้องน้ำสนาม | W18: 1 | X18: ห้อง | Y18: 0 | Z18: 0 | AA18: 0 | AB18: 0 | AC18: 0 | AD18: 0 | AE18: 0 | AF18: 1 | AG18: 0 | AH18: 0 | AI18: 0 | AJ18: 0 | AK18: 0
B19: Site | C19: ห้องน้ำสนาม 2 ห้อง | D19: =SUMIF(F19:T19,">0") -> 1 | E19: ตู้ | F19: =Y19+SUMIFS('บันทึกของเข้า-ออก'!$J:$J,'บันทึกของเข้า-ออก'!$B:$B,สรุป!$C19,'บันทึกของเข้า-ออก'!$L:$L,สรุป!F$5,'บันทึกของเข้า-ออก'!$I:$I,">="&สรุป!$F$2,'บันทึกของเข้า-ออก'!$I:$I,"<="&สรุป!$G$2)-SUMIFS('บันทึกของเข้า-ออก'!$E:$E,'บันทึกของเข้า-ออก'!$B:$B,สรุป!$C19,'บันทึกของเข้า-ออก'!$F:$F,สรุป!F$5,'บันทึกของเข้า-ออก'!$D:$D,">="&สรุป!$F$2,'บันทึกของเข้า-ออก'!$D:$D,"<="&สรุป!$G$2) -> 0 | G19: =Z19+SUMIFS('บันทึกของเข้า-ออก'!$J:$J,'บันทึกของเข้า-ออก'!$B:$B,สรุป!$C19,'บันทึกของเข้า-ออก'!$L:$L,สรุป!G$5,'บันทึกของเข้า-ออก'!$I:$I,">="&สรุป!$F$2,'บันทึกของเข้า-ออก'!$I:$I,"<="&สรุป!$G$2)-SUMIFS('บันทึกของเข้า-ออก'!$E:$E,'บันทึกของเข้า-ออก'!$B:$B,สรุป!$C19,'บันทึกของเข้า-ออก'!$F:$F,สรุป!G$5,'บันทึกของเข้า-ออก'!$D:$D,">="&สรุป!$F$2,'บันทึกของเข้า-ออก'!$D:$D,"<="&สรุป!$G$2) -> 0 | H19: =AA19+SUMIFS('บันทึกของเข้า-ออก'!$J:$J,'บันทึกของเข้า-ออก'!$B:$B,สรุป!$C19,'บันทึกของเข้า-ออก'!$L:$L,สรุป!H$5,'บันทึกของเข้า-ออก'!$I:$I,">="&สรุป!$F$2,'บันทึกของเข้า-ออก'!$I:$I,"<="&สรุป!$G$2)-SUMIFS('บันทึกของเข้า-ออก'!$E:$E,'บันทึกของเข้า-ออก'!$B:$B,สรุป!$C19,'บันทึกของเข้า-ออก'!$F:$F,สรุป!H$5,'บันทึกของเข้า-ออก'!$D:$D,">="&สรุป!$F$2,'บันทึกของเข้า-ออก'!$D:$D,"<="&สรุป!$G$2) -> 0 | I19: =AB19+SUMIFS('บันทึกของเข้า-ออก'!$J:$J,'บันทึกของเข้า-ออก'!$B:$B,สรุป!$C19,'บันทึกของเข้า-ออก'!$L:$L,สรุป!I$5,'บันทึกของเข้า-ออก'!$I:$I,">="&สรุป!$F$2,'บันทึกของเข้า-ออก'!$I:$I,"<="&สรุป!$G$2)-SUMIFS('บันทึกของเข้า-ออก'!$E:$E,'บันทึกของเข้า-ออก'!$B:$B,สรุป!$C19,'บันทึกของเข้า-ออก'!$F:$F,สรุป!I$5,'บันทึกของเข้า-ออก'!$D:$D,">="&สรุป!$F$2,'บันทึกของเข้า-ออก'!$D:$D,"<="&สรุป!$G$2) -> 0 | J19: =AC19+SUMIFS('บันทึกของเข้า-ออก'!$J:$J,'บันทึกของเข้า-ออก'!$B:$B,สรุป!$C19,'บันทึกของเข้า-ออก'!$L:$L,สรุป!J$5,'บันทึกของเข้า-ออก'!$I:$I,">="&สรุป!$F$2,'บันทึกของเข้า-ออก'!$I:$I,"<="&สรุป!$G$2)-SUMIFS('บันทึกของเข้า-ออก'!$E:$E,'บันทึกของเข้า-ออก'!$B:$B,สรุป!$C19,'บันทึกของเข้า-ออก'!$F:$F,สรุป!J$5,'บันทึกของเข้า-ออก'!$D:$D,">="&สรุป!$F$2,'บันทึกของเข้า-ออก'!$D:$D,"<="&สรุป!$G$2) -> 0 | K19: =AD19+SUMIFS('บันทึกของเข้า-ออก'!$J:$J,'บันทึกของเข้า-ออก'!$B:$B,สรุป!$C19,'บันทึกของเข้า-ออก'!$L:$L,สรุป!K$5,'บันทึกของเข้า-ออก'!$I:$I,">="&สรุป!$F$2,'บันทึกของเข้า-ออก'!$I:$I,"<="&สรุป!$G$2)-SUMIFS('บันทึกของเข้า-ออก'!$E:$E,'บันทึกของเข้า-ออก'!$B:$B,สรุป!$C19,'บันทึกของเข้า-ออก'!$F:$F,สรุป!K$5,'บันทึกของเข้า-ออก'!$D:$D,">="&สรุป!$F$2,'บันทึกของเข้า-ออก'!$D:$D,"<="&สรุป!$G$2) -> 0 | L19: =AE19+SUMIFS('บันทึกของเข้า-ออก'!$J:$J,'บันทึกของเข้า-ออก'!$B:$B,สรุป!$C19,'บันทึกของเข้า-ออก'!$L:$L,สรุป!L$5,'บันทึกของเข้า-ออก'!$I:$I,">="&สรุป!$F$2,'บันทึกของเข้า-ออก'!$I:$I,"<="&สรุป!$G$2)-SUMIFS('บันทึกของเข้า-ออก'!$E:$E,'บันทึกของเข้า-ออก'!$B:$B,สรุป!$C19,'บันทึกของเข้า-ออก'!$F:$F,สรุป!L$5,'บันทึกของเข้า-ออก'!$D:$D,">="&สรุป!$F$2,'บันทึกของเข้า-ออก'!$D:$D,"<="&สรุป!$G$2) -> 0 | M19: =AF19+SUMIFS('บันทึกของเข้า-ออก'!$J:$J,'บันทึกของเข้า-ออก'!$B:$B,สรุป!$C19,'บันทึกของเข้า-ออก'!$L:$L,สรุป!M$5,'บันทึกของเข้า-ออก'!$I:$I,">="&สรุป!$F$2,'บันทึกของเข้า-ออก'!$I:$I,"<="&สรุป!$G$2)-SUMIFS('บันทึกของเข้า-ออก'!$E:$E,'บันทึกของเข้า-ออก'!$B:$B,สรุป!$C19,'บันทึกของเข้า-ออก'!$F:$F,สรุป!M$5,'บันทึกของเข้า-ออก'!$D:$D,">="&สรุป!$F$2,'บันทึกของเข้า-ออก'!$D:$D,"<="&สรุป!$G$2) -> 1 | ... R19: =AK19+SUMIFS('บันทึกของเข้า-ออก'!$J:$J,'บันทึกของเข้า-ออก'!$B:$B,สรุป!$C19,'บันทึกของเข้า-ออก'!$L:$L,สรุป!R$5,'บันทึกของเข้า-ออก'!$I:$I,">="&สรุป!$F$2,'บันทึกของเข้า-ออก'!$I:$I,"<="&สรุป!$G$2)-SUMIFS('บันทึกของเข้า-ออก'!$E:$E,'บันทึกของเข้า-ออก'!$B:$B,สรุป!$C19,'บันทึกของเข้า-ออก'!$F:$F,สรุป!R$5,'บันทึกของเข้า-ออก'!$D:$D,">="&สรุป!$F$2,'บันทึกของเข้า-ออก'!$D:$D,"<="&สรุป!$G$2) -> 0 | V19: =C19 -> ห้องน้ำสนาม 2 ห้อง | W19: 1 | X19: ตู้ | Y19: 0 | Z19: 0 | AA19: 0 | AB19: 0 | AC19: 0 | AD19: 0 | AE19: 0 | AF19: 1 | AG19: 0 | AH19: 0 | AI19: 0 | AJ19: 0 | AK19: 0
B20: Site | C20: ตู้สนาม(ตู้คอนเทนเนอร์) | D20: =SUMIF(F20:T20,">0") -> 1 | E20: ตู้ | F20: =Y20+SUMIFS('บันทึกของเข้า-ออก'!$J:$J,'บันทึกของเข้า-ออก'!$B:$B,สรุป!$C20,'บันทึกของเข้า-ออก'!$L:$L,สรุป!F$5,'บันทึกของเข้า-ออก'!$I:$I,">="&สรุป!$F$2,'บันทึกของเข้า-ออก'!$I:$I,"<="&สรุป!$G$2)-SUMIFS('บันทึกของเข้า-ออก'!$E:$E,'บันทึกของเข้า-ออก'!$B:$B,สรุป!$C20,'บันทึกของเข้า-ออก'!$F:$F,สรุป!F$5,'บันทึกของเข้า-ออก'!$D:$D,">="&สรุป!$F$2,'บันทึกของเข้า-ออก'!$D:$D,"<="&สรุป!$G$2) -> 0 | G20: =Z20+SUMIFS('บันทึกของเข้า-ออก'!$J:$J,'บันทึกของเข้า-ออก'!$B:$B,สรุป!$C20,'บันทึกของเข้า-ออก'!$L:$L,สรุป!G$5,'บันทึกของเข้า-ออก'!$I:$I,">="&สรุป!$F$2,'บันทึกของเข้า-ออก'!$I:$I,"<="&สรุป!$G$2)-SUMIFS('บันทึกของเข้า-ออก'!$E:$E,'บันทึกของเข้า-ออก'!$B:$B,สรุป!$C20,'บันทึกของเข้า-ออก'!$F:$F,สรุป!G$5,'บันทึกของเข้า-ออก'!$D:$D,">="&สรุป!$F$2,'บันทึกของเข้า-ออก'!$D:$D,"<="&สรุป!$G$2) -> 0 | H20: =AA20+SUMIFS('บันทึกของเข้า-ออก'!$J:$J,'บันทึกของเข้า-ออก'!$B:$B,สรุป!$C20,'บันทึกของเข้า-ออก'!$L:$L,สรุป!H$5,'บันทึกของเข้า-ออก'!$I:$I,">="&สรุป!$F$2,'บันทึกของเข้า-ออก'!$I:$I,"<="&สรุป!$G$2)-SUMIFS('บันทึกของเข้า-ออก'!$E:$E,'บันทึกของเข้า-ออก'!$B:$B,สรุป!$C20,'บันทึกของเข้า-ออก'!$F:$F,สรุป!H$5,'บันทึกของเข้า-ออก'!$D:$D,">="&สรุป!$F$2,'บันทึกของเข้า-ออก'!$D:$D,"<="&สรุป!$G$2) -> 0 | I20: =AB20+SUMIFS('บันทึกของเข้า-ออก'!$J:$J,'บันทึกของเข้า-ออก'!$B:$B,สรุป!$C20,'บันทึกของเข้า-ออก'!$L:$L,สรุป!I$5,'บันทึกของเข้า-ออก'!$I:$I,">="&สรุป!$F$2,'บันทึกของเข้า-ออก'!$I:$I,"<="&สรุป!$G$2)-SUMIFS('บันทึกของเข้า-ออก'!$E:$E,'บันทึกของเข้า-ออก'!$B:$B,สรุป!$C20,'บันทึกของเข้า-ออก'!$F:$F,สรุป!I$5,'บันทึกของเข้า-ออก'!$D:$D,">="&สรุป!$F$2,'บันทึกของเข้า-ออก'!$D:$D,"<="&สรุป!$G$2) -> 0 | J20: =AC20+SUMIFS('บันทึกของเข้า-ออก'!$J:$J,'บันทึกของเข้า-ออก'!$B:$B,สรุป!$C20,'บันทึกของเข้า-ออก'!$L:$L,สรุป!J$5,'บันทึกของเข้า-ออก'!$I:$I,">="&สรุป!$F$2,'บันทึกของเข้า-ออก'!$I:$I,"<="&สรุป!$G$2)-SUMIFS('บันทึกของเข้า-ออก'!$E:$E,'บันทึกของเข้า-ออก'!$B:$B,สรุป!$C20,'บันทึกของเข้า-ออก'!$F:$F,สรุป!J$5,'บันทึกของเข้า-ออก'!$D:$D,">="&สรุป!$F$2,'บันทึกของเข้า-ออก'!$D:$D,"<="&สรุป!$G$2) -> 1 | K20: =AD20+SUMIFS('บันทึกของเข้า-ออก'!$J:$J,'บันทึกของเข้า-ออก'!$B:$B,สรุป!$C20,'บันทึกของเข้า-ออก'!$L:$L,สรุป!K$5,'บันทึกของเข้า-ออก'!$I:$I,">="&สรุป!$F$2,'บันทึกของเข้า-ออก'!$I:$I,"<="&สรุป!$G$2)-SUMIFS('บันทึกของเข้า-ออก'!$E:$E,'บันทึกของเข้า-ออก'!$B:$B,สรุป!$C20,'บันทึกของเข้า-ออก'!$F:$F,สรุป!K$5,'บันทึกของเข้า-ออก'!$D:$D,">="&สรุป!$F$2,'บันทึกของเข้า-ออก'!$D:$D,"<="&สรุป!$G$2) -> 0 | L20: =AE20+SUMIFS('บันทึกของเข้า-ออก'!$J:$J,'บันทึกของเข้า-ออก'!$B:$B,สรุป!$C20,'บันทึกของเข้า-ออก'!$L:$L,สรุป!L$5,'บันทึกของเข้า-ออก'!$I:$I,">="&สรุป!$F$2,'บันทึกของเข้า-ออก'!$I:$I,"<="&สรุป!$G$2)-SUMIFS('บันทึกของเข้า-ออก'!$E:$E,'บันทึกของเข้า-ออก'!$B:$B,สรุป!$C20,'บันทึกของเข้า-ออก'!$F:$F,สรุป!L$5,'บันทึกของเข้า-ออก'!$D:$D,">="&สรุป!$F$2,'บันทึกของเข้า-ออก'!$D:$D,"<="&สรุป!$G$2) -> 0 | M20: =AF20+SUMIFS('บันทึกของเข้า-ออก'!$J:$J,'บันทึกของเข้า-ออก'!$B:$B,สรุป!$C20,'บันทึกของเข้า-ออก'!$L:$L,สรุป!M$5,'บันทึกของเข้า-ออก'!$I:$I,">="&สรุป!$F$2,'บันทึกของเข้า-ออก'!$I:$I,"<="&สรุป!$G$2)-SUMIFS('บันทึกของเข้า-ออก'!$E:$E,'บันทึกของเข้า-ออก'!$B:$B,สรุป!$C20,'บันทึกของเข้า-ออก'!$F:$F,สรุป!M$5,'บันทึกของเข้า-ออก'!$D:$D,">="&สรุป!$F$2,'บันทึกของเข้า-ออก'!$D:$D,"<="&สรุป!$G$2) -> 0 | ... R20: =AK20+SUMIFS('บันทึกของเข้า-ออก'!$J:$J,'บันทึกของเข้า-ออก'!$B:$B,สรุป!$C20,'บันทึกของเข้า-ออก'!$L:$L,สรุป!R$5,'บันทึกของเข้า-ออก'!$I:$I,">="&สรุป!$F$2,'บันทึกของเข้า-ออก'!$I:$I,"<="&สรุป!$G$2)-SUMIFS('บันทึกของเข้า-ออก'!$E:$E,'บันทึกของเข้า-ออก'!$B:$B,สรุป!$C20,'บันทึกของเข้า-ออก'!$F:$F,สรุป!R$5,'บันทึกของเข้า-ออก'!$D:$D,">="&สรุป!$F$2,'บันทึกของเข้า-ออก'!$D:$D,"<="&สรุป!$G$2) -> 0 | V20: =C20 -> ตู้สนาม(ตู้คอนเทนเนอร์) | W20: 1 | X20: ตู้ | Y20: 0 | Z20: 0 | AA20: 0 | AB20: 0 | AC20: 1 | AD20: 0 | AE20: 0 | AF20: 0 | AG20: 0 | AH20: 0 | AI20: 0 | AJ20: 0 | AK20: 0
